Workbook
Name Años_préstamo: #REF!
Name Capital: #REF!
Name Datos: #REF!
Name Día_de_pago: DATE(YEAR(Inicio_prestamo),MONTH(Inicio_prestamo)+Payment_Number,DAY(Inicio_prestamo))
Name Fecha_de_pago: #REF!
Name Fila_de_encabezado: ROW(#REF!)
Name Importe_del_préstamo: #REF!
Name Impresión_completa: #REF!
Name Inicio_prestamo: #REF!
Name Int: #REF!
Name Int_acum: #REF!
Name Interés_total: #REF!
Name Núm_de_pago: #REF!
Name Núm_pagos_al_año: #REF!
Name Número_de_pagos: MATCH(0.01,Saldo_final,-1)+1
Name Pago_adicional: #REF!
Name Pago_mensual_programado: #REF!
Name Pago_progr: #REF!
Name Pago_total: #REF!
Name Pagos_adicionales_programados: #REF!
Name Restablecer_área_de_impresión: OFFSET(Impresión_completa,0,0,Última_fila)
Name Saldo_final: #REF!
Name Saldo_inicial: #REF!
Name Tasa_de_interés: #REF!
Name Tasa_de_interés_programada: #REF!
Name Última_fila: IF(Valores_especificados,Fila_de_encabezado+Número_de_pagos,Fila_de_encabezado)
Name Valores_especificados: IF(Importe_del_préstamo*Tasa_de_interés*Años_préstamo*Inicio_prestamo>0,1,0)

Sheet CORTE 4200
B1: Primavera 2026 | N1: Venta | O1: =+SUM(O10,O19,O28,O37,O46,O55,O64,O73,O82,O91,O100,O109,O118,O127,O136,O145,O154,O163,O172,O181,O190,O199,O217,O226,O244,O253,O262,O271,O280,O298,O307,O316,O325,O334,O343,O352,O361,O370,O379,O388,O397,O406,O415,O424,O433,O442,O451,O460,O469,O487,O496,O505,O523,O532,O541,O550,O559,O568,O577,O586,O595,O604,O613,O622,O631,O640,O649,O658,O667,O676,O685,O694,O703,O712,O721,O730,O739,O748,O757,O766,O775,O802,O820,O829,O838,'4219 Ex 4166'!AA4,O811,O784,O478,O235,O289,O793,O208,O514) -> 21161 | Q1: Mayor | S1: 1.2 | T1: 2.1 | U1: 2.4 | V1: 2.1 | W1: 1.5 | X1: 0.9 | Y1: =SUM(S1:X1) -> 10.2
D2: 4200 | N2: Giro | Q2: Tienda K | S2: 3 | T2: 5 | U2: 5 | V2: 4 | W2: 1 | X2: 1 | Y2: =SUM(S2:X2) -> 19
Q3: Tienda F | S3: 1 | T3: 2 | U3: 3 | V3: 2 | W3: 2 | X3: 1 | Y3: =SUM(S3:X3) -> 11
A6: 4200
A8: Art. | B8: TELA | E8: Obsv
A9: 4201-00 | B9: Ibiza Blue | C9: Tiro | D9: Cintura | F9: Tallas | G9: 34 | H9: 36 | I9: 38 | J9: 40 | K9: 42 | L9: 44 | M9: 46 | O9: TOTAL | Q9: Tallas | S9: 36 | T9: 38 | U9: 40 | V9: 42 | W9: 44 | X9: 46 | Z9: TOTAL
A10: =+A9 -> 4201-00 | B10: Fecha | F10: Venta | H10: ='BASE DATOS'!C4 -> 72 | I10: ='BASE DATOS'!D4 -> 158 | J10: ='BASE DATOS'!E4 -> 165 | K10: ='BASE DATOS'!F4 -> 158 | L10: ='BASE DATOS'!G4 -> 108 | M10: ='BASE DATOS'!H4 -> 87 | O10: =SUM(H10:N10) -> 748 | Z10: =SUBTOTAL(9,S10:Y10) -> 0 | AD10: 1137
A11: =+A10 -> 4201-00 | B11: 45979 | C11: Bota | D11: Pitillo | E11: Giro | F11: 11507 | H11: =78-H20 -> 39 | I11: =118-I20 -> 59 | J11: =124-J20 -> 62 | K11: =118-K20 -> 59 | L11: =78-L20 -> 39 | M11: =46-M20 -> 23 | O11: =SUM(H11:N11) -> 281 | Q11: Corte Total | Z11: =SUM(S11:Y11) -> 0 | AD11: 1579
A12: =+A11 -> 4201-00 | B12: 46043 | E12: Giro | F12: 11550 | H12: =50-H29-H21 -> 24 | I12: =100-I29-I21 -> 50 | J12: =120-J29-J21 -> 62 | K12: =100-K29-K21 -> 46 | L12: =90-L29-L21 -> 50 | M12: =60-M29-M21 -> 29 | O12: =SUM(H12:N12) -> 261 | Q12: Tienda K | R12: =78/19 -> 4.1052632 | Z12: =SUM(S12:Y12) -> 0 | AD12: =+AD11-AD10 -> 442
A13: =+A12 -> 4201-00 | B13: 46055 | D13: Bio Focalizado | E13: Giro | F13: 11553 | H13: 55 | I13: 110 | J13: 129 | K13: 110 | L13: 55 | M13: 38 | O13: =SUM(H13:N13) -> 497 | Q13: Tienda F | R13: =25/11 -> 2.2727273 | Z13: =SUM(S13:Y13) -> 0
A14: =+A13 -> 4201-00 | E14: Giro | O14: =SUM(H14:N14) -> 0 | Z14: =SUM(S14:Y14) -> 0
A15: =+A14 -> 4201-00 | E15: Giro | O15: =SUM(H15:N15) -> 0 | Q15: Mayor | R15: =500/10.2 -> 49.019608 | S15: =49*1.2 -> 58.8 | T15: =49*2.1 -> 102.9 | U15: =49*2.4 -> 117.6 | V15: =49*2.4 -> 117.6 | W15: =49*1.5 -> 73.5 | X15: =49*0.9 -> 44.1 | Z15: =SUM(S15:Y15) -> 514.5
A16: =+A15 -> 4201-00 | E16: Saldo | F16: =+B9 -> Ibiza Blue | H16: =+H10-H11-H12-H13-H15+H14 -> -46 | I16: =+I10-I11-I12-I13-I15+I14 -> -61 | J16: =+J10-J11-J12-J13-J15-J14 -> -88 | K16: =+K10-K11-K12-K13-K15-K14 -> -57 | L16: =+L10-L11-L12-L13-L15-L14 -> -36 | M16: =+M10-M11-M12-M13-M15-M14 -> -3 | O16: =SUM(H16:N16) -> -291 | S16: =SUM(S12:S15) -> 58.8 | T16: =SUM(T12:T15) -> 102.9 | U16: =SUM(U12:U15) -> 117.6 | V16: =SUM(V12:V15) -> 117.6 | W16: =SUM(W12:W15) -> 73.5 | X16: =SUM(X12:X15) -> 44.1 | Z16: =SUM(S16:Y16) -> 514.5
A17: Art. | B17: TELA | E17: Obsv
A18: 4201-01 | B18: Ibiza Blue | C18: Tiro | D18: Cintura | F18: Tallas | G18: 34 | H18: 36 | I18: 38 | J18: 40 | K18: 42 | L18: 44 | M18: 46 | O18: TOTAL | Q18: Tallas | S18: 36 | T18: 38 | U18: 40 | V18: 42 | W18: 44 | X18: 46 | Z18: TOTAL
A19: =+A18 -> 4201-01 | B19: Fecha | F19: Venta | H19: ='BASE DATOS'!C5 -> 34 | I19: ='BASE DATOS'!D5 -> 53 | J19: ='BASE DATOS'!E5 -> 60 | K19: ='BASE DATOS'!F5 -> 57 | L19: ='BASE DATOS'!G5 -> 41 | M19: ='BASE DATOS'!H5 -> 26 | O19: =SUM(H19:N19) -> 271 | Z19: =SUBTOTAL(9,S19:Y19) -> 0
A20: =+A19 -> 4201-01 | B20: 45979 | C20: Bota | D20: Pitillo | E20: Giro | F20: 11507 | H20: 39 | I20: 59 | J20: 62 | K20: 59 | L20: 39 | M20: 23 | O20: =SUM(H20:N20) -> 281 | Q20: Corte Total | Z20: =SUM(S20:Y20) -> 0
A21: =+A20 -> 4201-01 | E21: Giro | F21: 11550 | H21: 2 | I21: 8 | J21: 12 | K21: 10 | L21: 7 | M21: 8 | O21: =SUM(H21:N21) -> 47 | Q21: Tienda K | R21: =78/19 -> 4.1052632 | Z21: =SUM(S21:Y21) -> 0
A22: =+A21 -> 4201-01 | D22: Bio Focalizado Oxidado | E22: Giro | O22: =SUM(H22:N22) -> 0 | Q22: Tienda F | R22: =25/11 -> 2.2727273 | Z22: =SUM(S22:Y22) -> 0
A23: =+A22 -> 4201-01 | E23: Giro | O23: =SUM(H23:N23) -> 0 | Z23: =SUM(S23:Y23) -> 0
A24: =+A23 -> 4201-01 | E24: Giro | O24: =SUM(H24:N24) -> 0 | Q24: Mayor | R24: =500/10.2 -> 49.019608 | S24: =49*1.2 -> 58.8 | T24: =49*2.1 -> 102.9 | U24: =49*2.4 -> 117.6 | V24: =49*2.4 -> 117.6 | W24: =49*1.5 -> 73.5 | X24: =49*0.9 -> 44.1 | Z24: =SUM(S24:Y24) -> 514.5
A25: =+A24 -> 4201-01 | E25: Saldo | F25: =+B18 -> Ibiza Blue | H25: =+H19-H20-H21-H22-H24+H23 -> -7 | I25: =+I19-I20-I21-I22-I24+I23 -> -14 | J25: =+J19-J20-J21-J22-J24-J23 -> -14 | K25: =+K19-K20-K21-K22-K24-K23 -> -12 | L25: =+L19-L20-L21-L22-L24-L23 -> -5 | M25: =+M19-M20-M21-M22-M24-M23 -> -5 | O25: =SUM(H25:N25) -> -57 | S25: =SUM(S21:S24) -> 58.8 | T25: =SUM(T21:T24) -> 102.9 | U25: =SUM(U21:U24) -> 117.6 | V25: =SUM(V21:V24) -> 117.6 | W25: =SUM(W21:W24) -> 73.5 | X25: =SUM(X21:X24) -> 44.1 | Z25: =SUM(S25:Y25) -> 514.5
A26: Art. | B26: TELA | E26: Obsv
A27: 4201-60 | B27: Ibiza Blue | C27: Tiro | D27: Cintura | F27: Tallas | G27: 34 | H27: 36 | I27: 38 | J27: 40 | K27: 42 | L27: 44 | M27: 46 | O27: TOTAL | Q27: Tallas | S27: 36 | T27: 38 | U27: 40 | V27: 42 | W27: 44 | X27: 46 | Z27: TOTAL
A28: =+A27 -> 4201-60 | B28: Fecha | F28: Venta | H28: ='BASE DATOS'!C6 -> 21 | I28: ='BASE DATOS'!D6 -> 38 | J28: ='BASE DATOS'!E6 -> 42 | K28: ='BASE DATOS'!F6 -> 40 | L28: ='BASE DATOS'!G6 -> 31 | M28: ='BASE DATOS'!H6 -> 22 | O28: =SUM(H28:N28) -> 194 | Z28: =SUBTOTAL(9,S28:Y28) -> 0
A29: =+A28 -> 4201-60 | C29: Bota | D29: Pitillo | E29: Giro | F29: 11550 | H29: 24 | I29: 42 | J29: 46 | K29: 44 | L29: 33 | M29: 23 | O29: =SUM(H29:N29) -> 212 | Q29: Corte Total | Z29: =SUM(S29:Y29) -> 0
A30: =+A29 -> 4201-60 | E30: Giro | O30: =SUM(H30:N30) -> 0 | Q30: Tienda K | R30: =78/19 -> 4.1052632 | Z30: =SUM(S30:Y30) -> 0
A31: =+A30 -> 4201-60 | D31: Bio Focalizado | E31: Giro | O31: =SUM(H31:N31) -> 0 | Q31: Tienda F | R31: =25/11 -> 2.2727273 | Z31: =SUM(S31:Y31) -> 0
A32: =+A31 -> 4201-60 | D32: Tachas | E32: Giro | O32: =SUM(H32:N32) -> 0 | Z32: =SUM(S32:Y32) -> 0
A33: =+A32 -> 4201-60 | E33: Giro | O33: =SUM(H33:N33) -> 0 | Q33: Mayor | R33: =500/10.2 -> 49.019608 | S33: =49*1.2 -> 58.8 | T33: =49*2.1 -> 102.9 | U33: =49*2.4 -> 117.6 | V33: =49*2.4 -> 117.6 | W33: =49*1.5 -> 73.5 | X33: =49*0.9 -> 44.1 | Z33: =SUM(S33:Y33) -> 514.5
A34: =+A33 -> 4201-60 | E34: Saldo | F34: =+B27 -> Ibiza Blue | H34: =+H28-H29-H30-H31-H33+H32 -> -3 | I34: =+I28-I29-I30-I31-I33+I32 -> -4 | J34: =+J28-J29-J30-J31-J33-J32 -> -4 | K34: =+K28-K29-K30-K31-K33-K32 -> -4 | L34: =+L28-L29-L30-L31-L33-L32 -> -2 | M34: =+M28-M29-M30-M31-M33-M32 -> -1 | O34: =SUM(H34:N34) -> -18 | S34: =SUM(S30:S33) -> 58.8 | T34: =SUM(T30:T33) -> 102.9 | U34: =SUM(U30:U33) -> 117.6 | V34: =SUM(V30:V33) -> 117.6 | W34: =SUM(W30:W33) -> 73.5 | X34: =SUM(X30:X33) -> 44.1 | Z34: =SUM(S34:Y34) -> 514.5
A35: Art. | B35: TELA | E35: Obsv | AC35: Giro | AD35: 46085 | AE35: 36 | AF35: 38 | AG35: 40 | AH35: 42 | AI35: 44 | AJ35: 46 | AK35: Total
A36: 4202 | B36: Ibiza Blue | C36: Tiro | D36: Cintura | F36: Tallas | G36: 34 | H36: 36 | I36: 38 | J36: 40 | K36: 42 | L36: 44 | M36: 46 | O36: TOTAL | Q36: Tallas | S36: 36 | T36: 38 | U36: 40 | V36: 42 | W36: 44 | X36: 46 | Z36: TOTAL | AC36: O.Corte | AD36: 11566 | AF36: 68 | AG36: 88 | AH36: 78 | AI36: 54 | AJ36: 48 | AK36: =SUM(AE36:AJ36) -> 336
A37: =+A36 -> 4202 | B37: Fecha | D37: =+B36 -> Ibiza Blue | F37: Venta | H37: ='BASE DATOS'!C7 -> 85 | I37: ='BASE DATOS'!D7 -> 181 | J37: ='BASE DATOS'!E7 -> 196 | K37: ='BASE DATOS'!F7 -> 188 | L37: ='BASE DATOS'!G7 -> 127 | M37: ='BASE DATOS'!H7 -> 99 | O37: =SUM(H37:N37) -> 876 | Z37: =SUBTOTAL(9,S37:Y37) -> 0 | AC37: Artículo | AD37: 4202
A38: =+A37 -> 4202 | B38: 45986 | C38: Bota | D38: Recto | E38: Giro | F38: 11514 | H38: 78 | I38: 100 | J38: 100 | K38: 100 | L38: 78 | M38: 50 | O38: =SUM(H38:N38) -> 506 | Q38: Corte Total | Z38: =SUM(S38:Y38) -> 0 | AC38: Tela | AD38: Ibiza Blue
A39: =+A38 -> 4202 | B39: 46085 | D39: EX 4189 | E39: Giro | F39: 11566 | I39: 90 | J39: 90 | K39: 100 | L39: 65 | M39: 60 | O39: =SUM(H39:N39) -> 405 | Q39: Tienda K | R39: =78/19 -> 4.1052632 | Z39: =SUM(S39:Y39) -> 0 | AC39: Tiro | AD39: Cintura
A40: =+A39 -> 4202 | E40: Giro | Q40: Tienda F | R40: =25/11 -> 2.2727273 | Z40: =SUM(S40:Y40) -> 0 | AC40: Bota | AD40: Recto
A41: =+A40 -> 4202 | E41: Giro | O41: =SUM(H41:N41) -> 0 | Z41: =SUM(S41:Y41) -> 0
A42: =+A41 -> 4202 | E42: Giro | O42: =SUM(H42:N42) -> 0 | Q42: Mayor | R42: =500/10.2 -> 49.019608 | S42: =49*1.2 -> 58.8 | T42: =49*2.1 -> 102.9 | U42: =49*2.4 -> 117.6 | V42: =49*2.4 -> 117.6 | W42: =49*1.5 -> 73.5 | X42: =49*0.9 -> 44.1 | Z42: =SUM(S42:Y42) -> 514.5
A43: =+A42 -> 4202 | E43: Saldo | F43: =+B36 -> Ibiza Blue | H43: =+H37-H38-H39-H40-H42+H41 -> 7 | I43: =+I37-I38-I39-I40-I42+I41 -> -9 | J43: =+J37-J38-J39-J40-J42-J41 -> 6 | K43: =+K37-K38-K39-K40-K42-K41 -> -12 | L43: =+L37-L38-L39-L40-L42-L41 -> -16 | M43: =+M37-M38-M39-M40-M42-M41 -> -11 | O43: =SUM(H43:N43) -> -35 | S43: =SUM(S39:S42) -> 58.8 | T43: =SUM(T39:T42) -> 102.9 | U43: =SUM(U39:U42) -> 117.6 | V43: =SUM(V39:V42) -> 117.6 | W43: =SUM(W39:W42) -> 73.5 | X43: =SUM(X39:X42) -> 44.1 | Z43: =SUM(S43:Y43) -> 514.5
...

Sheet BASE DATOS
A1: Venta | B1: 4200 | D1: S | E1: M | F1: L | G1: XL | J1: =$J$98 -> 21166
A2: Artículo | C2: 36 | D2: 38 | E2: 40 | F2: 42 | G2: 44 | H2: 46 | J2: Total | K2: Girar o | L2: Compra | M2: Girar
A3: c | B3: c2 | C3: c3 | D3: c4 | E3: c5 | F3: c6 | G3: c7 | H3: c8 | I3: c9 | J3: c10 | K3: Disponible | L3: Kennedy | P3: 46105 | Q3: 13,01 hrs | AC3: 46098 | AD3: 12,00 hrs | AP3: 46093 | AQ3: 15,25 hrs | BC3: 46092 | BD3: 12,2 hrs | BP3: 46090 | BQ3: 10,21 hrs | CC3: 46079 | CD3: 12,01 hrs | CP3: 46072 | CQ3: 0.55555556 | DC3: 46071 | DD3: 0.5 | DP3: 46070 | DQ3: 0.71597222 | EC3: 46066 | ED3: 0.57986111 | EP3: 46065 | EQ3: 0.58888889 | FC3: 46062 | FD3: 12,39 hrs | FP3: 46062 | FQ3: 10 hrs | GC3: 46048 | GP3: 46045
A4: 1420100 | B4: Ibiza Blue | C4: 72 | D4: 158 | E4: 165 | F4: 158 | G4: 108 | H4: 87 | J4: =SUM(C4:H4) -> 748 | K4: ='CORTE 4200'!$O$16 -> -291 | L4: 50 | O4: 1420100 | P4: J MHC CINTURA P | Q4: Ventas | S4: 72 | T4: 158 | U4: 165 | V4: 158 | W4: 108 | X4: 87 | Y4: 0 | Z4: =SUM(S4:Y4) -> 748 | AB4: 1420100 | AC4: J MHC CINTURA P | AD4: Ventas | AF4: 74 | AG4: 157 | AH4: 168 | AI4: 156 | AJ4: 106 | AK4: 80 | AL4: 0 | AM4: =SUM(AF4:AL4) -> 741 | AN4: =+Tabla15[[#This Row],[c10]]-AM4 -> 7 | AO4: 1420100 | AP4: J MHC CINTURA P | AQ4: Ventas | AS4: 72 | AT4: 155 | AU4: 166 | AV4: 154 | AW4: 105 | AX4: 79 | AY4: 0 | AZ4: =SUM(AS4:AY4) -> 731 | BB4: 1420100 | BC4: J MHC CINTURA P | BD4: Ventas | BF4: 64 | BG4: 143 | BH4: 154 | BI4: 142 | BJ4: 102 | BK4: 76 | BL4: 0 | BM4: 681 | BO4: 1420100 | BP4: J MHC CINTURA P | BQ4: Ventas | BS4: 66 | BT4: 146 | BU4: 157 | BV4: 144 | BW4: 103 | BX4: 76 | BY4: 0 | BZ4: =SUM(BS4:BY4) -> 692 | CB4: 1420100 | CC4: J MHC CINTURA P | CD4: Ventas | CF4: 64 | CG4: 143 | CH4: 155 | CI4: 142 | CJ4: 101 | CK4: 75 | CL4: 0 | CM4: =SUM(CF4:CL4) -> 680 | CO4: 1420100 | CP4: J MHC CINTURA P | CQ4: Ventas | CS4: 60 | CT4: 137 | CU4: 149 | CV4: 137 | CW4: 98 | CX4: 74 | CY4: 0 | CZ4: 655 | DB4: 1420100 | DC4: J MHC CINTURA P | DD4: Ventas | DF4: 57 | DG4: 132 | DH4: 141 | DI4: 131 | DJ4: 93 | DK4: 70 | DL4: 0 | DM4: 624 | DO4: 1420100 | DP4: J MHC CINTURA P | DQ4: Ventas | DS4: 49 | DT4: 117 | DU4: 123 | DV4: 117 | DW4: 83 | DX4: 66 | DY4: 0 | DZ4: 555 | EB4: 1420100 | EC4: J MHC CINTURA P | ED4: Ventas | EF4: 45 | EG4: 107 | EH4: 115 | EI4: 111 | EJ4: 80 | EK4: 64 | EL4: 0 | EM4: 522 | EO4: 1420100 | EP4: J MHC CINTURA P | EQ4: Ventas | ES4: 42 | ET4: 102 | EU4: 110 | EV4: 106 | EW4: 77 | EX4: 62 | EY4: 0 | EZ4: 499 | FB4: 1420100 | FC4: J MHC CINTURA P | FD4: Ventas | FF4: 38 | FG4: 92 | FH4: 99 | FI4: 97 | FJ4: 70 | FK4: 60 | FL4: 0 | FM4: 456 | FO4: 1420100 | FP4: J MHC CINTURA P | FQ4: Ventas | FS4: 36 | FT4: 86 | FU4: 93 | FV4: 91 | FW4: 66 | FX4: 56 | FY4: 0 | FZ4: 428 | GB4: 1420100 | GC4: J MHC CINTURA P | GD4: Ventas | GF4: 19 | GG4: 32 | GH4: 38 | GI4: 36 | GJ4: 29 | GK4: 20 | GL4: 0 | GM4: 174 | GO4: 1420100 | GP4: J MHC CINTURA P | GQ4: Ventas | GS4: 18 | GT4: 29 | GU4: 34 | GV4: 33 | GW4: 27 | GX4: 19 | GY4: 0 | GZ4: =SUM(GS4:GY4) -> 160
A5: 1420101 | B5: Ibiza Blue | C5: 34 | D5: 53 | E5: 60 | F5: 57 | G5: 41 | H5: 26 | J5: =SUM(C5:H5) -> 271 | K5: ='CORTE 4200'!$O$25 -> -57 | O5: 1420101 | P5: J MHC CINTURA P | Q5: Ventas | S5: 34 | T5: 53 | U5: 60 | V5: 57 | W5: 41 | X5: 26 | Y5: 0 | Z5: =SUM(S5:Y5) -> 271 | AB5: 1420101 | AC5: J MHC CINTURA P | AD5: Ventas | AF5: 34 | AG5: 53 | AH5: 60 | AI5: 57 | AJ5: 41 | AK5: 26 | AL5: 0 | AM5: =SUM(AF5:AL5) -> 271 | AO5: 1420101 | AP5: J MHC CINTURA P | AQ5: Ventas | AS5: 34 | AT5: 53 | AU5: 60 | AV5: 57 | AW5: 41 | AX5: 26 | AY5: 0 | AZ5: =SUM(AS5:AY5) -> 271 | BB5: 1420101 | BC5: J MHC CINTURA P | BD5: Ventas | BF5: 33 | BG5: 50 | BH5: 57 | BI5: 55 | BJ5: 40 | BK5: 26 | BL5: 0 | BM5: 261 | BO5: 1420101 | BP5: J MHC CINTURA P | BQ5: Ventas | BS5: 33 | BT5: 50 | BU5: 57 | BV5: 55 | BW5: 40 | BX5: 26 | BY5: 0 | BZ5: =SUM(BS5:BY5) -> 261 | CB5: 1420101 | CC5: J MHC CINTURA P | CD5: Ventas | CF5: 33 | CG5: 50 | CH5: 57 | CI5: 55 | CJ5: 40 | CK5: 26 | CL5: 0 | CM5: =SUM(CF5:CL5) -> 261 | CO5: 1420101 | CP5: J MHC CINTURA P | CQ5: Ventas | CS5: 33 | CT5: 48 | CU5: 55 | CV5: 52 | CW5: 37 | CX5: 24 | CY5: 0 | CZ5: 249 | DB5: 1420101 | DC5: J MHC CINTURA P | DD5: Ventas | DF5: 33 | DG5: 48 | DH5: 55 | DI5: 52 | DJ5: 37 | DK5: 24 | DL5: 0 | DM5: 249 | DO5: 1420101 | DP5: J MHC CINTURA P | DQ5: Ventas | DS5: 30 | DT5: 44 | DU5: 51 | DV5: 49 | DW5: 35 | DX5: 24 | DY5: 0 | DZ5: 233 | EB5: 1420101 | EC5: J MHC CINTURA P | ED5: Ventas | EF5: 30 | EG5: 44 | EH5: 51 | EI5: 49 | EJ5: 35 | EK5: 24 | EL5: 0 | EM5: 233 | EO5: 1420101 | EP5: J MHC CINTURA P | EQ5: Ventas | ES5: 28 | ET5: 41 | EU5: 48 | EV5: 46 | EW5: 33 | EX5: 23 | EY5: 0 | EZ5: 219 | FB5: 1420101 | FC5: J MHC CINTURA P | FD5: Ventas | FF5: 26 | FG5: 36 | FH5: 43 | FI5: 41 | FJ5: 30 | FK5: 21 | FL5: 0 | FM5: 197 | FO5: 1420101 | FP5: J MHC CINTURA P | FQ5: Ventas | FS5: 26 | FT5: 36 | FU5: 43 | FV5: 41 | FW5: 30 | FX5: 21 | FY5: 0 | FZ5: 197 | GB5: 1420101 | GC5: J MHC CINTURA P | GD5: Ventas | GF5: 21 | GG5: 27 | GH5: 32 | GI5: 31 | GJ5: 24 | GK5: 18 | GL5: 0 | GM5: 153 | GO5: 1420101 | GP5: J MHC CINTURA P | GQ5: Ventas | GS5: 18 | GT5: 22 | GU5: 25 | GV5: 25 | GW5: 20 | GX5: 15 | GY5: 0 | GZ5: =SUM(GS5:GY5) -> 125
A6: 1420160 | B6: Ibiza Blue | C6: 21 | D6: 38 | E6: 42 | F6: 40 | G6: 31 | H6: 22 | J6: =SUM(C6:H6) -> 194 | K6: ='CORTE 4200'!$O$34 -> -18 | O6: 1420160 | P6: J MHC CINTURA P | Q6: Ventas | S6: 21 | T6: 38 | U6: 42 | V6: 40 | W6: 31 | X6: 22 | Y6: 0 | Z6: =SUM(S6:Y6) -> 194 | AB6: 1420160 | AC6: J MHC CINTURA P | AD6: Ventas | AF6: 21 | AG6: 38 | AH6: 42 | AI6: 40 | AJ6: 31 | AK6: 22 | AL6: 0 | AM6: =SUM(AF6:AL6) -> 194 | AO6: 1420160 | AP6: J MHC CINTURA P | AQ6: Ventas | AS6: 21 | AT6: 36 | AU6: 40 | AV6: 38 | AW6: 29 | AX6: 20 | AY6: 0 | AZ6: =SUM(AS6:AY6) -> 184 | BB6: 1420160 | BC6: J MHC CINTURA P | BD6: Ventas | BF6: 21 | BG6: 36 | BH6: 40 | BI6: 38 | BJ6: 29 | BK6: 20 | BL6: 0 | BM6: =SUM(BF6:BL6) -> 184 | BO6: 1420160 | BP6: J MHC CINTURA P | BQ6: Ventas | BS6: 21 | BT6: 36 | BU6: 40 | BV6: 38 | BW6: 29 | BX6: 20 | BY6: 0 | BZ6: =SUM(BS6:BY6) -> 184 | CB6: 1420160 | CC6: J MHC CINTURA P | CD6: Ventas | CF6: 19 | CG6: 33 | CH6: 37 | CI6: 36 | CJ6: 27 | CK6: 19 | CL6: 0 | CM6: =SUM(CF6:CL6) -> 171 | CO6: 1420160 | CP6: J MHC CINTURA P | CQ6: Ventas | CS6: 19 | CT6: 33 | CU6: 37 | CV6: 36 | CW6: 27 | CX6: 19 | CY6: 0 | CZ6: 171 | DB6: 1420160 | DC6: J MHC CINTURA P | DD6: Ventas | DF6: 19 | DG6: 33 | DH6: 37 | DI6: 36 | DJ6: 27 | DK6: 19 | DL6: 0 | DM6: 171 | DO6: 1420160 | DP6: J MHC CINTURA P | DQ6: Ventas | DS6: 19 | DT6: 32 | DU6: 36 | DV6: 35 | DW6: 27 | DX6: 19 | DY6: 0 | DZ6: 168 | EB6: 1420160 | EC6: J MHC CINTURA P | ED6: Ventas | EF6: 19 | EG6: 32 | EH6: 36 | EI6: 35 | EJ6: 27 | EK6: 19 | EL6: 0 | EM6: 168 | EO6: 1420160 | EP6: J MHC CINTURA P | EQ6: Ventas | ES6: 17 | ET6: 29 | EU6: 33 | EV6: 32 | EW6: 25 | EX6: 18 | EY6: 0 | EZ6: 154 | FB6: 1420160 | FC6: J MHC CINTURA P | FD6: Ventas | FF6: 13 | FG6: 22 | FH6: 26 | FI6: 25 | FJ6: 19 | FK6: 14 | FL6: 0 | FM6: 119 | FO6: 1420160 | FP6: J MHC CINTURA P | FQ6: Ventas | FS6: 13 | FT6: 22 | FU6: 26 | FV6: 25 | FW6: 19 | FX6: 14 | FY6: 0 | FZ6: 119 | GB6: 1420160 | GC6: J MHC CINTURA P | GD6: Ventas | GF6: 9 | GG6: 14 | GH6: 19 | GI6: 19 | GJ6: 15 | GK6: 11 | GL6: 0 | GM6: 87 | GO6: 1420160 | GP6: J MHC CINTURA P | GQ6: Ventas | GS6: 9 | GT6: 14 | GU6: 19 | GV6: 19 | GW6: 15 | GX6: 11 | GY6: 0 | GZ6: =SUM(GS6:GY6) -> 87
A7: 1420200 | B7: Ibiza Blue | C7: 85 | D7: 181 | E7: 196 | F7: 188 | G7: 127 | H7: 99 | J7: =SUM(C7:H7) -> 876 | K7: ='CORTE 4200'!$O$43 -> -35 | L7: 50 | O7: 1420200 | P7: J MHC CINTURA R | Q7: Ventas | S7: 85 | T7: 181 | U7: 196 | V7: 188 | W7: 127 | X7: 99 | Y7: 0 | Z7: =SUM(S7:Y7) -> 876 | AB7: 1420200 | AC7: J MHC CINTURA R | AD7: Ventas | AF7: 84 | AG7: 178 | AH7: 193 | AI7: 185 | AJ7: 126 | AK7: 98 | AL7: 0 | AM7: =SUM(AF7:AL7) -> 864 | AO7: 1420200 | AP7: J MHC CINTURA R | AQ7: Ventas | AS7: 84 | AT7: 176 | AU7: 191 | AV7: 183 | AW7: 124 | AX7: 96 | AY7: 0 | AZ7: =SUM(AS7:AY7) -> 854 | BB7: 1420200 | BC7: J MHC CINTURA R | BD7: Ventas | BF7: 74 | BG7: 159 | BH7: 173 | BI7: 167 | BJ7: 119 | BK7: 92 | BL7: 0 | BM7: =SUM(BF7:BL7) -> 784 | BO7: 1420200 | BP7: J MHC CINTURA R | BQ7: Ventas | BS7: 72 | BT7: 156 | BU7: 170 | BV7: 165 | BW7: 118 | BX7: 92 | BY7: 0 | BZ7: =SUM(BS7:BY7) -> 773 | CB7: 1420200 | CC7: J MHC CINTURA R | CD7: Ventas | CF7: 68 | CG7: 151 | CH7: 165 | CI7: 160 | CJ7: 114 | CK7: 90 | CL7: 0 | CM7: =SUM(CF7:CL7) -> 748 | CO7: 1420200 | CP7: J MHC CINTURA R | CQ7: Ventas | CS7: 67 | CT7: 145 | CU7: 159 | CV7: 154 | CW7: 110 | CX7: 88 | CY7: 0 | CZ7: 723 | DB7: 1420200 | DC7: J MHC CINTURA R | DD7: Ventas | DF7: 63 | DG7: 138 | DH7: 148 | DI7: 141 | DJ7: 98 | DK7: 79 | DL7: 0 | DM7: 667 | DO7: 1420200 | DP7: J MHC CINTURA R | DQ7: Ventas | DS7: 56 | DT7: 123 | DU7: 128 | DV7: 126 | DW7: 87 | DX7: 73 | DY7: 0 | DZ7: 593 | EB7: 1420200 | EC7: J MHC CINTURA R | ED7: Ventas | EF7: 53 | EG7: 117 | EH7: 123 | EI7: 121 | EJ7: 83 | EK7: 70 | EL7: 0 | EM7: 567 | EO7: 1420200 | EP7: J MHC CINTURA R | EQ7: Ventas | ES7: 50 | ET7: 112 | EU7: 118 | EV7: 116 | EW7: 80 | EX7: 68 | EY7: 0 | EZ7: 544 | FB7: 1420200 | FC7: J MHC CINTURA R | FD7: Ventas | FF7: 41 | FG7: 97 | FH7: 103 | FI7: 101 | FJ7: 69 | FK7: 61 | FL7: 0 | FM7: 472 | FO7: 1420200 | FP7: J MHC CINTURA R | FQ7: Ventas | FS7: 39 | FT7: 91 | FU7: 97 | FV7: 95 | FW7: 65 | FX7: 57 | FY7: 0 | FZ7: 444 | GB7: 1420200 | GC7: J MHC CINTURA R | GD7: Ventas | GF7: 12 | GG7: 21 | GH7: 25 | GI7: 23 | GJ7: 18 | GK7: 13 | GL7: 0 | GM7: 112 | GO7: 1420200 | GP7: J MHC CINTURA R | GQ7: Ventas | GS7: 9 | GT7: 16 | GU7: 18 | GV7: 17 | GW7: 14 | GX7: 10 | GY7: 0 | GZ7: =SUM(GS7:GY7) -> 84
A8: 1420300 | B8: B2868-V3 | C8: 4 | D8: 9 | E8: 9 | F8: 7 | G8: 2 | H8: 1 | J8: =SUM(C8:H8) -> 32 | K8: ='CORTE 4200'!$O$52 -> -1 | O8: 1420300 | P8: J MHC MEDIO TOB | Q8: Ventas | S8: 4 | T8: 9 | U8: 9 | V8: 7 | W8: 2 | X8: 1 | Y8: 0 | Z8: =SUM(S8:Y8) -> 32 | AB8: 1420300 | AC8: J MHC MEDIO TOB | AD8: Ventas | AF8: 4 | AG8: 9 | AH8: 9 | AI8: 7 | AJ8: 2 | AK8: 1 | AL8: 0 | AM8: =SUM(AF8:AL8) -> 32 | AO8: 1420300 | AP8: J MHC MEDIO TOB | AQ8: Ventas | AS8: 4 | AT8: 9 | AU8: 9 | AV8: 7 | AW8: 2 | AX8: 1 | AY8: 0 | AZ8: =SUM(AS8:AY8) -> 32 | BB8: 1420300 | BC8: J MHC MEDIO TOB | BD8: Ventas | BF8: 4 | BG8: 9 | BH8: 9 | BI8: 7 | BJ8: 2 | BK8: 1 | BL8: 0 | BM8: =SUM(BF8:BL8) -> 32 | BO8: 1420300 | BP8: J MHC MEDIO TOB | BQ8: Ventas | BS8: 4 | BT8: 9 | BU8: 9 | BV8: 7 | BW8: 2 | BX8: 1 | BY8: 0 | BZ8: =SUM(BS8:BY8) -> 32 | CB8: 1420300 | CC8: J MHC MEDIO TOB | CD8: Ventas | CF8: 4 | CG8: 9 | CH8: 9 | CI8: 7 | CJ8: 2 | CK8: 1 | CL8: 0 | CM8: =SUM(CF8:CL8) -> 32 | CO8: 1420300 | CP8: J MHC MEDIO TOB | CQ8: Ventas | CS8: 4 | CT8: 9 | CU8: 9 | CV8: 7 | CW8: 2 | CX8: 1 | CY8: 0 | CZ8: 32 | DB8: 1420300 | DC8: J MHC MEDIO TOB | DD8: Ventas | DF8: 4 | DG8: 9 | DH8: 9 | DI8: 7 | DJ8: 2 | DK8: 1 | DL8: 0 | DM8: 32 | DO8: 1420300 | DP8: J MHC MEDIO TOB | DQ8: Ventas | DS8: 4 | DT8: 9 | DU8: 9 | DV8: 7 | DW8: 2 | DX8: 1 | DY8: 0 | DZ8: 32 | EB8: 1420300 | EC8: J MHC MEDIO TOB | ED8: Ventas | EF8: 4 | EG8: 9 | EH8: 9 | EI8: 7 | EJ8: 2 | EK8: 1 | EL8: 0 | EM8: 32 | EO8: 1420300 | EP8: J MHC MEDIO TOB | EQ8: Ventas | ES8: 4 | ET8: 9 | EU8: 9 | EV8: 7 | EW8: 2 | EX8: 1 | EY8: 0 | EZ8: 32 | FB8: 1420300 | FC8: J MHC MEDIO TOB | FD8: Ventas | FF8: 1 | FG8: 3 | FH8: 3 | FI8: 2 | FJ8: 1 | FK8: 1 | FL8: 0 | FM8: 11 | FO8: 1420300 | FP8: J MHC MEDIO TOB | FQ8: Ventas | FS8: 1 | FT8: 3 | FU8: 3 | FV8: 2 | FW8: 1 | FX8: 1 | FY8: 0 | FZ8: 11 | GB8: 1420300 | GC8: J MHC MEDIO TOB | GD8: Ventas | GF8: 1 | GG8: 3 | GH8: 3 | GI8: 2 | GJ8: 1 | GK8: 1 | GL8: 0 | GM8: 11 | GO8: 1420300 | GP8: J MHC MEDIO TOB | GQ8: Ventas | GS8: 1 | GT8: 3 | GU8: 3 | GV8: 2 | GW8: 1 | GX8: 1 | GY8: 0 | GZ8: =SUM(GS8:GY8) -> 11
A9: 1420301 | B9: B2868-V3 | C9: 31 | D9: 62 | E9: 59 | F9: 58 | G9: 40 | H9: 35 | J9: =SUM(C9:H9) -> 285 | K9: ='CORTE 4200'!$O$61 -> -88 | O9: 1420301 | P9: J MHC MEDIO TOB | Q9: Ventas | S9: 31 | T9: 62 | U9: 59 | V9: 58 | W9: 40 | X9: 35 | Y9: 0 | Z9: =SUM(S9:Y9) -> 285 | AB9: 1420301 | AC9: J MHC MEDIO TOB | AD9: Ventas | AF9: 31 | AG9: 62 | AH9: 59 | AI9: 58 | AJ9: 40 | AK9: 35 | AL9: 0 | AM9: =SUM(AF9:AL9) -> 285 | AO9: 1420301 | AP9: J MHC MEDIO TOB | AQ9: Ventas | AS9: 31 | AT9: 62 | AU9: 59 | AV9: 58 | AW9: 40 | AX9: 35 | AY9: 0 | AZ9: =SUM(AS9:AY9) -> 285 | BB9: 1420301 | BC9: J MHC MEDIO TOB | BD9: Ventas | BF9: 31 | BG9: 62 | BH9: 59 | BI9: 58 | BJ9: 40 | BK9: 35 | BL9: 0 | BM9: =SUM(BF9:BL9) -> 285 | BO9: 1420301 | BP9: J MHC MEDIO TOB | BQ9: Ventas | BS9: 31 | BT9: 62 | BU9: 59 | BV9: 58 | BW9: 40 | BX9: 35 | BY9: 0 | BZ9: =SUM(BS9:BY9) -> 285 | CB9: 1420301 | CC9: J MHC MEDIO TOB | CD9: Ventas | CF9: 31 | CG9: 62 | CH9: 59 | CI9: 58 | CJ9: 40 | CK9: 35 | CL9: 0 | CM9: =SUM(CF9:CL9) -> 285 | CO9: 1420301 | CP9: J MHC MEDIO TOB | CQ9: Ventas | CS9: 31 | CT9: 62 | CU9: 59 | CV9: 58 | CW9: 40 | CX9: 35 | CY9: 0 | CZ9: 285 | DB9: 1420301 | DC9: J MHC MEDIO TOB | DD9: Ventas | DF9: 31 | DG9: 62 | DH9: 59 | DI9: 58 | DJ9: 40 | DK9: 35 | DL9: 0 | DM9: 285 | DO9: 1420301 | DP9: J MHC MEDIO TOB | DQ9: Ventas | DS9: 31 | DT9: 62 | DU9: 59 | DV9: 58 | DW9: 40 | DX9: 35 | DY9: 0 | DZ9: 285 | EB9: 1420301 | EC9: J MHC MEDIO TOB | ED9: Ventas | EF9: 31 | EG9: 62 | EH9: 59 | EI9: 58 | EJ9: 40 | EK9: 35 | EL9: 0 | EM9: 285 | EO9: 1420301 | EP9: J MHC MEDIO TOB | EQ9: Ventas | ES9: 30 | ET9: 60 | EU9: 57 | EV9: 56 | EW9: 39 | EX9: 34 | EY9: 0 | EZ9: 276 | FB9: 1420301 | FC9: J MHC MEDIO TOB | FD9: Ventas | FF9: 26 | FG9: 54 | FH9: 51 | FI9: 50 | FJ9: 35 | FK9: 30 | FL9: 0 | FM9: 246 | FO9: 1420301 | FP9: J MHC MEDIO TOB | FQ9: Ventas | FS9: 26 | FT9: 54 | FU9: 51 | FV9: 50 | FW9: 35 | FX9: 30 | FY9: 0 | FZ9: 246 | GB9: 1420301 | GC9: J MHC MEDIO TOB | GD9: Ventas | GF9: 15 | GG9: 21 | GH9: 18 | GI9: 17 | GJ9: 13 | GK9: 8 | GL9: 0 | GM9: 92 | GO9: 1420301 | GP9: J MHC MEDIO TOB | GQ9: Ventas | GS9: 15 | GT9: 21 | GU9: 18 | GV9: 17 | GW9: 13 | GX9: 8 | GY9: 0 | GZ9: =SUM(GS9:GY9) -> 92
A10: 1420400 | B10: B2868-V3 | C10: 39 | D10: 82 | E10: 90 | F10: 81 | G10: 54 | H10: 40 | J10: =SUM(C10:H10) -> 386 | K10: ='CORTE 4200'!$O$70 -> -27 | L10: 50 | O10: 1420400 | P10: J MHC MEDIO FLA | Q10: Ventas | S10: 39 | T10: 82 | U10: 90 | V10: 81 | W10: 54 | X10: 40 | Y10: 0 | Z10: =SUM(S10:Y10) -> 386 | AB10: 1420400 | AC10: J MHC MEDIO FLA | AD10: Ventas | AF10: 39 | AG10: 82 | AH10: 90 | AI10: 81 | AJ10: 54 | AK10: 40 | AL10: 0 | AM10: =SUM(AF10:AL10) -> 386 | AO10: 1420400 | AP10: J MHC MEDIO FLA | AQ10: Ventas | AS10: 39 | AT10: 80 | AU10: 88 | AV10: 79 | AW10: 52 | AX10: 38 | AY10: 0 | AZ10: =SUM(AS10:AY10) -> 376 | BB10: 1420400 | BC10: J MHC MEDIO FLA | BD10: Ventas | BF10: 31 | BG10: 68 | BH10: 76 | BI10: 67 | BJ10: 49 | BK10: 35 | BL10: 0 | BM10: =SUM(BF10:BL10) -> 326 | BO10: 1420400 | BP10: J MHC MEDIO FLA | BQ10: Ventas | BS10: 31 | BT10: 68 | BU10: 76 | BV10: 67 | BW10: 49 | BX10: 35 | BY10: 0 | BZ10: =SUM(BS10:BY10) -> 326 | CB10: 1420400 | CC10: J MHC MEDIO FLA | CD10: Ventas | CF10: 29 | CG10: 66 | CH10: 74 | CI10: 65 | CJ10: 47 | CK10: 33 | CL10: 0 | CM10: =SUM(CF10:CL10) -> 314 | CO10: 1420400 | CP10: J MHC MEDIO FLA | CQ10: Ventas | CS10: 29 | CT10: 66 | CU10: 74 | CV10: 65 | CW10: 47 | CX10: 33 | CY10: 0 | CZ10: 314 | DB10: 1420400 | DC10: J MHC MEDIO FLA | DD10: Ventas | DF10: 28 | DG10: 64 | DH10: 72 | DI10: 63 | DJ10: 45 | DK10: 32 | DL10: 0 | DM10: 304 | DO10: 1420400 | DP10: J MHC MEDIO FLA | DQ10: Ventas | DS10: 21 | DT10: 51 | DU10: 55 | DV10: 52 | DW10: 39 | DX10: 28 | DY10: 0 | DZ10: 246 | EB10: 1420400 | EC10: J MHC MEDIO FLA | ED10: Ventas | EF10: 18 | EG10: 44 | EH10: 49 | EI10: 46 | EJ10: 35 | EK10: 25 | EL10: 0 | EM10: 217 | EO10: 1420400 | EP10: J MHC MEDIO FLA | EQ10: Ventas | ES10: 18 | ET10: 44 | EU10: 49 | EV10: 46 | EW10: 35 | EX10: 25 | EY10: 0 | EZ10: 217 | FB10: 1420400 | FC10: J MHC MEDIO FLA | FD10: Ventas | FF10: 15 | FG10: 39 | FH10: 44 | FI10: 41 | FJ10: 30 | FK10: 23 | FL10: 0 | FM10: 192 | FO10: 1420400 | FP10: J MHC MEDIO FLA | FQ10: Ventas | FS10: 15 | FT10: 39 | FU10: 44 | FV10: 41 | FW10: 30 | FX10: 23 | FY10: 0 | FZ10: 192 | GB10: 1420400 | GC10: J MHC MEDIO FLA | GD10: Ventas | GF10: 8 | GG10: 23 | GH10: 28 | GI10: 25 | GJ10: 19 | GK10: 12 | GL10: 0 | GM10: 115 | GO10: 1420400 | GP10: J MHC MEDIO FLA | GQ10: Ventas | GS10: 7 | GT10: 20 | GU10: 24 | GV10: 22 | GW10: 17 | GX10: 11 | GY10: 0 | GZ10: =SUM(GS10:GY10) -> 101
A11: 1420401 | B11: B2868-V3 | C11: 2 | D11: 6 | E11: 9 | F11: 8 | G11: 7 | H11: 5 | J11: =SUM(C11:H11) -> 37 | K11: ='CORTE 4200'!$O$79 -> 2 | O11: 1420401 | P11: J MHC MEDIO FLA | Q11: Ventas | S11: 2 | T11: 6 | U11: 9 | V11: 8 | W11: 7 | X11: 5 | Y11: 0 | Z11: =SUM(S11:Y11) -> 37 | AB11: 1420401 | AC11: J MHC MEDIO FLA | AD11: Ventas | AF11: 0 | AG11: 4 | AH11: 8 | AI11: 8 | AJ11: 7 | AK11: 5 | AL11: 0 | AM11: =SUM(AF11:AL11) -> 32 | AO11: 1420401 | AP11: J MHC MEDIO FLA | AQ11: Ventas | AS11: 0 | AT11: 4 | AU11: 8 | AV11: 8 | AW11: 7 | AX11: 5 | AY11: 0 | AZ11: =SUM(AS11:AY11) -> 32 | BB11: 1420401 | BC11: J MHC MEDIO FLA | BD11: Ventas | BF11: 0 | BG11: 4 | BH11: 8 | BI11: 8 | BJ11: 7 | BK11: 5 | BL11: 0 | BM11: =SUM(BF11:BL11) -> 32 | BO11: 1420401 | BP11: J MHC MEDIO FLA | BQ11: Ventas | BS11: 0 | BT11: 4 | BU11: 8 | BV11: 8 | BW11: 7 | BX11: 5 | BY11: 0 | BZ11: =SUM(BS11:BY11) -> 32 | CB11: 1420401 | CC11: J MHC MEDIO FLA | CD11: Ventas | CF11: 0 | CG11: 4 | CH11: 8 | CI11: 8 | CJ11: 7 | CK11: 5 | CL11: 0 | CM11: =SUM(CF11:CL11) -> 32 | CO11: 1420401 | CP11: J MHC MEDIO FLA | CQ11: Ventas | CS11: 0 | CT11: 4 | CU11: 8 | CV11: 8 | CW11: 7 | CX11: 5 | CY11: 0 | CZ11: 32 | DB11: 1420401 | DC11: J MHC MEDIO FLA | DD11: Ventas | DF11: 0 | DG11: 4 | DH11: 8 | DI11: 8 | DJ11: 7 | DK11: 5 | DL11: 0 | DM11: 32 | DO11: 1420401 | DP11: J MHC MEDIO FLA | DQ11: Ventas | DS11: 0 | DT11: 4 | DU11: 8 | DV11: 8 | DW11: 7 | DX11: 5 | DY11: 0 | DZ11: 32 | EB11: 1420401 | EC11: J MHC MEDIO FLA | ED11: Ventas | EF11: 0 | EG11: 4 | EH11: 8 | EI11: 8 | EJ11: 7 | EK11: 5 | EL11: 0 | EM11: 32 | EO11: 1420401 | EP11: J MHC MEDIO FLA | EQ11: Ventas | ES11: 0 | ET11: 4 | EU11: 8 | EV11: 8 | EW11: 7 | EX11: 5 | EY11: 0 | EZ11: 32 | FB11: 1420401 | FC11: J MHC MEDIO FLA | FD11: Ventas | FF11: 0 | FG11: 4 | FH11: 8 | FI11: 8 | FJ11: 7 | FK11: 5 | FL11: 0 | FM11: 32 | FO11: 1420401 | FP11: J MHC MEDIO FLA | FQ11: Ventas | FS11: 0 | FT11: 4 | FU11: 8 | FV11: 8 | FW11: 7 | FX11: 5 | FY11: 0 | FZ11: 32 | GB11: 1420401 | GC11: J MHC MEDIO FLA | GD11: Ventas | GF11: 0 | GG11: 4 | GH11: 8 | GI11: 8 | GJ11: 7 | GK11: 5 | GL11: 0 | GM11: 32 | GO11: 1420401 | GP11: J MHC MEDIO FLA | GQ11: Ventas | GS11: 0 | GT11: 4 | GU11: 8 | GV11: 8 | GW11: 7 | GX11: 5 | GY11: 0 | GZ11: =SUM(GS11:GY11) -> 32
A12: 1420402 | B12: B2868-V3 | C12: 31 | D12: 78 | E12: 83 | F12: 80 | G12: 56 | H12: 48 | J12: =SUM(C12:H12) -> 376 | K12: ='CORTE 4200'!$O$88 -> -16 | O12: 1420402 | P12: J MHC MEDIO FLA | Q12: Ventas | S12: 31 | T12: 78 | U12: 83 | V12: 80 | W12: 56 | X12: 48 | Y12: 0 | Z12: =SUM(S12:Y12) -> 376 | AB12: 1420402 | AC12: J MHC MEDIO FLA | AD12: Ventas | AF12: 33 | AG12: 83 | AH12: 88 | AI12: 82 | AJ12: 57 | AK12: 48 | AL12: 0 | AM12: =SUM(AF12:AL12) -> 391 | AO12: 1420402 | AP12: J MHC MEDIO FLA | AQ12: Ventas | AS12: 33 | AT12: 81 | AU12: 86 | AV12: 80 | AW12: 55 | AX12: 46 | AY12: 0 | AZ12: =SUM(AS12:AY12) -> 381 | BB12: 1420402 | BC12: J MHC MEDIO FLA | BD12: Ventas | BF12: 33 | BG12: 81 | BH12: 86 | BI12: 80 | BJ12: 55 | BK12: 46 | BL12: 0 | BM12: =SUM(BF12:BL12) -> 381 | BO12: 1420402 | BP12: J MHC MEDIO FLA | BQ12: Ventas | BS12: 33 | BT12: 81 | BU12: 86 | BV12: 80 | BW12: 55 | BX12: 46 | BY12: 0 | BZ12: =SUM(BS12:BY12) -> 381 | CB12: 1420402 | CC12: J MHC MEDIO FLA | CD12: Ventas | CF12: 33 | CG12: 81 | CH12: 86 | CI12: 80 | CJ12: 55 | CK12: 46 | CL12: 0 | CM12: =SUM(CF12:CL12) -> 381 | CO12: 1420402 | CP12: J MHC MEDIO FLA | CQ12: Ventas | CS12: 33 | CT12: 81 | CU12: 86 | CV12: 80 | CW12: 55 | CX12: 46 | CY12: 0 | CZ12: 381 | DB12: 1420402 | DC12: J MHC MEDIO FLA | DD12: Ventas | DF12: 31 | DG12: 78 | DH12: 83 | DI12: 77 | DJ12: 53 | DK12: 45 | DL12: 0 | DM12: 367 | DO12: 1420402 | DP12: J MHC MEDIO FLA | DQ12: Ventas | DS12: 28 | DT12: 74 | DU12: 79 | DV12: 74 | DW12: 51 | DX12: 45 | DY12: 0 | DZ12: 351 | EB12: 1420402 | EC12: J MHC MEDIO FLA | ED12: Ventas | EF12: 26 | EG12: 69 | EH12: 74 | EI12: 72 | EJ12: 50 | EK12: 45 | EL12: 0 | EM12: 336 | EO12: 1420402 | EP12: J MHC MEDIO FLA | EQ12: Ventas | ES12: 26 | ET12: 69 | EU12: 74 | EV12: 72 | EW12: 50 | EX12: 45 | EY12: 0 | EZ12: 336 | FB12: 1420402 | FC12: J MHC MEDIO FLA | FD12: Ventas | FF12: 24 | FG12: 66 | FH12: 71 | FI12: 69 | FJ12: 48 | FK12: 43 | FL12: 0 | FM12: 321 | FO12: 1420402 | FP12: J MHC MEDIO FLA | FQ12: Ventas | FS12: 22 | FT12: 60 | FU12: 65 | FV12: 63 | FW12: 44 | FX12: 39 | FY12: 0 | FZ12: 293 | GB12: 1420402 | GC12: J MHC MEDIO FLA | GD12: Ventas | GF12: 8 | GG12: 18 | GH12: 23 | GI12: 21 | GJ12: 16 | GK12: 11 | GL12: 0 | GM12: 97 | GO12: 1420402 | GP12: J MHC MEDIO FLA | GQ12: Ventas | GS12: 7 | GT12: 15 | GU12: 19 | GV12: 18 | GW12: 14 | GX12: 10 | GY12: 0 | GZ12: =SUM(GS12:GY12) -> 83
A13: 1420500 | B13: Ayla | C13: 60 | D13: 119 | E13: 124 | F13: 121 | G13: 80 | H13: 66 | J13: =SUM(C13:H13) -> 570 | K13: ='CORTE 4200'!$O$97 -> -148 | L13: 50 | O13: 1420500 | P13: J MHC CINTURA O | Q13: Ventas | S13: 60 | T13: 119 | U13: 124 | V13: 121 | W13: 80 | X13: 66 | Y13: 0 | Z13: =SUM(S13:Y13) -> 570 | AB13: 1420500 | AC13: J MHC CINTURA O | AD13: Ventas | AF13: 60 | AG13: 119 | AH13: 123 | AI13: 120 | AJ13: 80 | AK13: 66 | AL13: 0 | AM13: =SUM(AF13:AL13) -> 568 | AO13: 1420500 | AP13: J MHC CINTURA O | AQ13: Ventas | AS13: 60 | AT13: 117 | AU13: 121 | AV13: 118 | AW13: 78 | AX13: 64 | AY13: 0 | AZ13: =SUM(AS13:AY13) -> 558 | BB13: 1420500 | BC13: J MHC CINTURA O | BD13: Ventas | BF13: 52 | BG13: 105 | BH13: 109 | BI13: 106 | BJ13: 75 | BK13: 61 | BL13: 0 | BM13: =SUM(BF13:BL13) -> 508 | BO13: 1420500 | BP13: J MHC CINTURA O | BQ13: Ventas | BS13: 52 | BT13: 105 | BU13: 109 | BV13: 106 | BW13: 75 | BX13: 61 | BY13: 0 | BZ13: =SUM(BS13:BY13) -> 508 | CB13: 1420500 | CC13: J MHC CINTURA O | CD13: Ventas | CF13: 52 | CG13: 105 | CH13: 109 | CI13: 106 | CJ13: 75 | CK13: 61 | CL13: 0 | CM13: =SUM(CF13:CL13) -> 508 | CO13: 1420500 | CP13: J MHC CINTURA O | CQ13: Ventas | CS13: 52 | CT13: 104 | CU13: 108 | CV13: 105 | CW13: 74 | CX13: 61 | CY13: 0 | CZ13: 504 | DB13: 1420500 | DC13: J MHC CINTURA O | DD13: Ventas | DF13: 51 | DG13: 101 | DH13: 104 | DI13: 101 | DJ13: 70 | DK13: 59 | DL13: 0 | DM13: 486 | DO13: 1420500 | DP13: J MHC CINTURA O | DQ13: Ventas | DS13: 51 | DT13: 99 | DU13: 101 | DV13: 98 | DW13: 67 | DX13: 57 | DY13: 0 | DZ13: 473 | EB13: 1420500 | EC13: J MHC CINTURA O | ED13: Ventas | EF13: 51 | EG13: 99 | EH13: 101 | EI13: 98 | EJ13: 67 | EK13: 57 | EL13: 0 | EM13: 473 | EO13: 1420500 | EP13: J MHC CINTURA O | EQ13: Ventas | ES13: 46 | ET13: 93 | EU13: 95 | EV13: 93 | EW13: 64 | EX13: 54 | EY13: 0 | EZ13: 445 | FB13: 1420500 | FC13: J MHC CINTURA O | FD13: Ventas | FF13: 46 | FG13: 93 | FH13: 95 | FI13: 93 | FJ13: 64 | FK13: 54 | FL13: 0 | FM13: 445 | FO13: 1420500 | FP13: J MHC CINTURA O | FQ13: Ventas | FS13: 44 | FT13: 87 | FU13: 89 | FV13: 87 | FW13: 60 | FX13: 50 | FY13: 0 | FZ13: 417 | GB13: 1420500 | GC13: J MHC CINTURA O | GD13: Ventas | GF13: 21 | GG13: 31 | GH13: 33 | GI13: 30 | GJ13: 22 | GK13: 14 | GL13: 0 | GM13: 151 | GO13: 1420500 | GP13: J MHC CINTURA O | GQ13: Ventas | GS13: 18 | GT13: 26 | GU13: 26 | GV13: =14+10 -> 24 | GW13: =20-10+8 -> 18 | GX13: =13-8+6 -> 11 | GZ13: =SUM(GS13:GY13) -> 123
A14: 1420501 | B14: Ayla | C14: 35 | D14: 78 | E14: 87 | F14: 85 | G14: 62 | H14: 54 | J14: =SUM(C14:H14) -> 401 | K14: ='CORTE 4200'!$O$106 -> -6 | O14: 1420501 | P14: J MHC CINTURA O | Q14: Ventas | S14: 35 | T14: 78 | U14: 87 | V14: 85 | W14: 62 | X14: 54 | Y14: 0 | Z14: =SUM(S14:Y14) -> 401 | AB14: 1420501 | AC14: J MHC CINTURA O | AD14: Ventas | AF14: 35 | AG14: 78 | AH14: 87 | AI14: 85 | AJ14: 62 | AK14: 54 | AL14: 0 | AM14: =SUM(AF14:AL14) -> 401 | AO14: 1420501 | AP14: J MHC CINTURA O | AQ14: Ventas | AS14: 35 | AT14: 78 | AU14: 87 | AV14: 85 | AW14: 62 | AX14: 54 | AY14: 0 | AZ14: =SUM(AS14:AY14) -> 401 | BB14: 1420501 | BC14: J MHC CINTURA O | BD14: Ventas | BF14: 34 | BG14: 76 | BH14: 84 | BI14: 83 | BJ14: 61 | BK14: 53 | BL14: 0 | BM14: =SUM(BF14:BL14) -> 391 | BO14: 1420501 | BP14: J MHC CINTURA O | BQ14: Ventas | BS14: 32 | BT14: 72 | BU14: 80 | BV14: 80 | BW14: 59 | BX14: 52 | BY14: 0 | BZ14: =SUM(BS14:BY14) -> 375 | CB14: 1420501 | CC14: J MHC CINTURA O | CD14: Ventas | CF14: 30 | CG14: 70 | CH14: 78 | CI14: 77 | CJ14: 57 | CK14: 52 | CL14: 0 | CM14: =SUM(CF14:CL14) -> 364 | CO14: 1420501 | CP14: J MHC CINTURA O | CQ14: Ventas | CS14: 30 | CT14: 70 | CU14: 78 | CV14: 77 | CW14: 57 | CX14: 52 | CY14: 0 | CZ14: 364 | DB14: 1420501 | DC14: J MHC CINTURA O | DD14: Ventas | DF14: 30 | DG14: 69 | DH14: 74 | DI14: 71 | DJ14: 51 | DK14: 46 | DL14: 0 | DM14: 341 | DO14: 1420501 | DP14: J MHC CINTURA O | DQ14: Ventas | DS14: 30 | DT14: 69 | DU14: 74 | DV14: 71 | DW14: 51 | DX14: 46 | DY14: 0 | DZ14: 341 | EB14: 1420501 | EC14: J MHC CINTURA O | ED14: Ventas | EF14: 30 | EG14: 69 | EH14: 74 | EI14: 71 | EJ14: 51 | EK14: 46 | EL14: 0 | EM14: 341 | EO14: 1420501 | EP14: J MHC CINTURA O | EQ14: Ventas | ES14: 29 | ET14: 67 | EU14: 72 | EV14: 69 | EW14: 49 | EX14: 44 | EY14: 0 | EZ14: 330 | FB14: 1420501 | FC14: J MHC CINTURA O | FD14: Ventas | FF14: 22 | FG14: 56 | FH14: 60 | FI14: 59 | FJ14: 42 | FK14: 38 | FL14: 0 | FM14: 277 | FO14: 1420501 | FP14: J MHC CINTURA O | FQ14: Ventas | FS14: 22 | FT14: 56 | FU14: 60 | FV14: 59 | FW14: 42 | FX14: 38 | FY14: 0 | FZ14: 277 | GB14: 1420501 | GC14: J MHC CINTURA O | GD14: Ventas | GF14: 9 | GG14: 17 | GH14: 21 | GI14: 20 | GJ14: 16 | GK14: 12 | GL14: 0 | GM14: 95 | GO14: 1420501 | GP14: J MHC CINTURA O | GQ14: Ventas | GS14: 9 | GT14: 17 | GU14: 21 | GV14: 20 | GW14: 16 | GX14: 12 | GY14: 0 | GZ14: =SUM(GS14:GY14) -> 95
A15: 1420502 | B15: Ayla | C15: 0 | D15: 4 | E15: 8 | F15: 8 | G15: 7 | H15: 5 | J15: =SUM(C15:H15) -> 32 | K15: ='CORTE 4200'!$O$115 -> 0 | O15: 1420502 | P15: J MHC CINTURA O | Q15: Ventas | S15: 0 | T15: 4 | U15: 8 | V15: 8 | W15: 7 | X15: 5 | Y15: 0 | Z15: =SUM(S15:Y15) -> 32 | AB15: 1420502 | AC15: J MHC CINTURA O | AD15: Ventas | AF15: 0 | AG15: 4 | AH15: 8 | AI15: 8 | AJ15: 7 | AK15: 5 | AL15: 0 | AM15: =SUM(AF15:AL15) -> 32 | AO15: 1420502 | AP15: J MHC CINTURA O | AQ15: Ventas | AS15: 0 | AT15: 4 | AU15: 8 | AV15: 8 | AW15: 7 | AX15: 5 | AY15: 0 | AZ15: =SUM(AS15:AY15) -> 32 | BB15: 1420502 | BC15: J MHC CINTURA O | BD15: Ventas | BF15: 0 | BG15: 4 | BH15: 8 | BI15: 8 | BJ15: 7 | BK15: 5 | BL15: 0 | BM15: =SUM(BF15:BL15) -> 32 | BO15: 1420502 | BP15: J MHC CINTURA O | BQ15: Ventas | BS15: 0 | BT15: 4 | BU15: 8 | BV15: 8 | BW15: 7 | BX15: 5 | BY15: 0 | BZ15: =SUM(BS15:BY15) -> 32 | CB15: 1420502 | CC15: J MHC CINTURA O | CD15: Ventas | CF15: 0 | CG15: 4 | CH15: 8 | CI15: 8 | CJ15: 7 | CK15: 5 | CL15: 0 | CM15: =SUM(CF15:CL15) -> 32 | CO15: 1420502 | CP15: J MHC CINTURA O | CQ15: Ventas | CS15: 0 | CT15: 4 | CU15: 8 | CV15: 8 | CW15: 7 | CX15: 5 | CY15: 0 | CZ15: 32 | DB15: 1420502 | DC15: J MHC CINTURA O | DD15: Ventas | DF15: 0 | DG15: 4 | DH15: 8 | DI15: 8 | DJ15: 7 | DK15: 5 | DL15: 0 | DM15: 32 | DO15: 1420502 | DP15: J MHC CINTURA O | DQ15: Ventas | DS15: 0 | DT15: 4 | DU15: 8 | DV15: 8 | DW15: 7 | DX15: 5 | DY15: 0 | DZ15: 32 | EB15: 1420502 | EC15: J MHC CINTURA O | ED15: Ventas | EF15: 0 | EG15: 4 | EH15: 8 | EI15: 8 | EJ15: 7 | EK15: 5 | EL15: 0 | EM15: 32 | EO15: 1420502 | EP15: J MHC CINTURA O | EQ15: Ventas | ES15: 0 | ET15: 4 | EU15: 8 | EV15: 8 | EW15: 7 | EX15: 5 | EY15: 0 | EZ15: 32 | FB15: 1420502 | FC15: J MHC CINTURA O | FD15: Ventas | FF15: 0 | FG15: 4 | FH15: 8 | FI15: 8 | FJ15: 7 | FK15: 5 | FL15: 0 | FM15: 32 | FO15: 1420502 | FP15: J MHC CINTURA O | FQ15: Ventas | FS15: 0 | FT15: 4 | FU15: 8 | FV15: 8 | FW15: 7 | FX15: 5 | FY15: 0 | FZ15: 32 | GB15: 1420502 | GC15: J MHC CINTURA O | GD15: Ventas | GF15: 0 | GG15: 4 | GH15: 8 | GI15: 8 | GJ15: 7 | GK15: 5 | GL15: 0 | GM15: 32 | GO15: 1420502 | GP15: J MHC CINTURA O | GQ15: Ventas | GS15: 0 | GT15: 4 | GU15: 8 | GV15: 8 | GW15: 7 | GX15: 5 | GY15: 0 | GZ15: =SUM(GS15:GY15) -> 32
A16: 1420600 | B16: B2868-V3 | C16: 35 | D16: 71 | E16: 70 | F16: 63 | G16: 40 | H16: 26 | J16: =SUM(C16:H16) -> 305 | K16: ='CORTE 4200'!$O$124 -> -201 | L16: 50 | O16: 1420600 | P16: J MHC CINTURA P | Q16: Ventas | S16: 35 | T16: 71 | U16: 70 | V16: 63 | W16: 40 | X16: 26 | Y16: 0 | Z16: =SUM(S16:Y16) -> 305 | AB16: 1420600 | AC16: J MHC CINTURA P | AD16: Ventas | AF16: 35 | AG16: 69 | AH16: 68 | AI16: 62 | AJ16: 40 | AK16: 26 | AL16: 0 | AM16: =SUM(AF16:AL16) -> 300 | AO16: 1420600 | AP16: J MHC CINTURA P | AQ16: Ventas | AS16: 33 | AT16: 67 | AU16: 66 | AV16: 60 | AW16: 39 | AX16: 25 | AY16: 0 | AZ16: =SUM(AS16:AY16) -> 290 | BB16: 1420600 | BC16: J MHC CINTURA P | BD16: Ventas | BF16: 25 | BG16: 55 | BH16: 54 | BI16: 48 | BJ16: 36 | BK16: 22 | BL16: 0 | BM16: =SUM(BF16:BL16) -> 240 | BO16: 1420600 | BP16: J MHC CINTURA P | BQ16: Ventas | BS16: 25 | BT16: 55 | BU16: 54 | BV16: 48 | BW16: 36 | BX16: 22 | BY16: 0 | BZ16: =SUM(BS16:BY16) -> 240 | CB16: 1420600 | CC16: J MHC CINTURA P | CD16: Ventas | CF16: 21 | CG16: 50 | CH16: 49 | CI16: 42 | CJ16: 32 | CK16: 21 | CL16: 0 | CM16: =SUM(CF16:CL16) -> 215 | CO16: 1420600 | CP16: J MHC CINTURA P | CQ16: Ventas | CS16: 20 | CT16: 47 | CU16: 46 | CV16: 39 | CW16: 30 | CX16: 20 | CY16: 0 | CZ16: 202 | DB16: 1420600 | DC16: J MHC CINTURA P | DD16: Ventas | DF16: 18 | DG16: 43 | DH16: 40 | DI16: 35 | DJ16: 26 | DK16: 16 | DL16: 0 | DM16: 178 | DO16: 1420600 | DP16: J MHC CINTURA P | DQ16: Ventas | DS16: 15 | DT16: 37 | DU16: 35 | DV16: 32 | DW16: 24 | DX16: 16 | DY16: 0 | DZ16: 159 | EB16: 1420600 | EC16: J MHC CINTURA P | ED16: Ventas | EF16: 14 | EG16: 33 | EH16: 32 | EI16: 29 | EJ16: 22 | EK16: 14 | EL16: 0 | EM16: 144 | EO16: 1420600 | EP16: J MHC CINTURA P | EQ16: Ventas | ES16: 13 | ET16: 31 | EU16: 30 | EV16: 27 | EW16: 21 | EX16: 13 | EY16: 0 | EZ16: 135 | FB16: 1420600 | FC16: J MHC CINTURA P | FD16: Ventas | FF16: 9 | FG16: 23 | FH16: 22 | FI16: 20 | FJ16: 15 | FK16: 10 | FL16: 0 | FM16: 99 | FO16: 1420600 | FP16: J MHC CINTURA P | FQ16: Ventas | FS16: 9 | FT16: 23 | FU16: 22 | FV16: 20 | FW16: 15 | FX16: 10 | FY16: 0 | FZ16: 99 | GB16: 1420600 | GC16: J MHC CINTURA P | GD16: Ventas | GF16: 4 | GG16: 12 | GH16: 11 | GI16: 9 | GJ16: 6 | GK16: 2 | GL16: 0 | GM16: 44 | GO16: 1420600 | GP16: J MHC CINTURA P | GQ16: Ventas | GS16: 3 | GT16: 9 | GU16: 7 | GV16: 6 | GW16: 4 | GX16: 1 | GY16: 0 | GZ16: =SUM(GS16:GY16) -> 30
A17: 1420700 | B17: Ayla | C17: 0 | D17: 4 | E17: 8 | F17: 8 | G17: 7 | H17: 5 | J17: =SUM(C17:H17) -> 32 | K17: ='CORTE 4200'!$O$133 -> 32 | O17: 1420700 | P17: J MHC MEDIO OXF | Q17: Ventas | S17: 0 | T17: 4 | U17: 8 | V17: 8 | W17: 7 | X17: 5 | Y17: 0 | Z17: =SUM(S17:Y17) -> 32 | AB17: 1420700 | AC17: J MHC MEDIO OXF | AD17: Ventas | AF17: 0 | AG17: 4 | AH17: 8 | AI17: 8 | AJ17: 7 | AK17: 5 | AL17: 0 | AM17: =SUM(AF17:AL17) -> 32 | AO17: 1420700 | AP17: J MHC MEDIO OXF | AQ17: Ventas | AS17: 0 | AT17: 4 | AU17: 8 | AV17: 8 | AW17: 7 | AX17: 5 | AY17: 0 | AZ17: =SUM(AS17:AY17) -> 32 | BB17: 1420700 | BC17: J MHC MEDIO OXF | BD17: Ventas | BF17: 0 | BG17: 4 | BH17: 8 | BI17: 8 | BJ17: 7 | BK17: 5 | BL17: 0 | BM17: =SUM(BF17:BL17) -> 32 | BO17: 1420700 | BP17: J MHC MEDIO OXF | BQ17: Ventas | BS17: 0 | BT17: 4 | BU17: 8 | BV17: 8 | BW17: 7 | BX17: 5 | BY17: 0 | BZ17: =SUM(BS17:BY17) -> 32 | CB17: 1420700 | CC17: J MHC MEDIO OXF | CD17: Ventas | CF17: 0 | CG17: 4 | CH17: 8 | CI17: 8 | CJ17: 7 | CK17: 5 | CL17: 0 | CM17: =SUM(CF17:CL17) -> 32 | CO17: 1420700 | CP17: J MHC MEDIO OXF | CQ17: Ventas | CS17: 0 | CT17: 4 | CU17: 8 | CV17: 8 | CW17: 7 | CX17: 5 | CY17: 0 | CZ17: 32 | DB17: 1420700 | DC17: J MHC MEDIO OXF | DD17: Ventas | DF17: 0 | DG17: 4 | DH17: 8 | DI17: 8 | DJ17: 7 | DK17: 5 | DL17: 0 | DM17: 32 | DO17: 1420700 | DP17: J MHC MEDIO OXF | DQ17: Ventas | DS17: 0 | DT17: 4 | DU17: 8 | DV17: 8 | DW17: 7 | DX17: 5 | DY17: 0 | DZ17: 32 | EB17: 1420700 | EC17: J MHC MEDIO OXF | ED17: Ventas | EF17: 0 | EG17: 4 | EH17: 8 | EI17: 8 | EJ17: 7 | EK17: 5 | EL17: 0 | EM17: 32 | EO17: 1420700 | EP17: J MHC MEDIO OXF | EQ17: Ventas | ES17: 0 | ET17: 4 | EU17: 8 | EV17: 8 | EW17: 7 | EX17: 5 | EY17: 0 | EZ17: 32 | FB17: 1420700 | FC17: J MHC MEDIO OXF | FD17: Ventas | FF17: 0 | FG17: 4 | FH17: 8 | FI17: 8 | FJ17: 7 | FK17: 5 | FL17: 0 | FM17: 32 | FO17: 1420700 | FP17: J MHC MEDIO OXF | FQ17: Ventas | FS17: 0 | FT17: 4 | FU17: 8 | FV17: 8 | FW17: 7 | FX17: 5 | FY17: 0 | FZ17: 32 | GB17: 1420700 | GC17: J MHC MEDIO OXF | GD17: Ventas | GF17: 0 | GG17: 4 | GH17: 8 | GI17: 8 | GJ17: 7 | GK17: 5 | GL17: 0 | GM17: 32 | GO17: 1420700 | GP17: J MHC MEDIO OXF | GQ17: Ventas | GS17: 0 | GT17: 4 | GU17: 8 | GV17: 8 | GW17: 7 | GX17: 5 | GY17: 0 | GZ17: =SUM(GS17:GY17) -> 32
A18: 1420800 | B18: Ayla | C18: 10 | D18: 29 | E18: 38 | F18: 30 | G18: 22 | H18: 15 | J18: =SUM(C18:H18) -> 144 | K18: ='CORTE 4200'!$O$142 -> -44 | M18: Girar | O18: 1420800 | P18: J MHC CINTURA F | Q18: Ventas | S18: 10 | T18: 29 | U18: 38 | V18: 30 | W18: 22 | X18: 15 | Y18: 0 | Z18: =SUM(S18:Y18) -> 144 | AB18: 1420800 | AC18: J MHC CINTURA F | AD18: Ventas | AF18: 10 | AG18: 29 | AH18: 38 | AI18: 30 | AJ18: 22 | AK18: 15 | AL18: 0 | AM18: =SUM(AF18:AL18) -> 144 | AO18: 1420800 | AP18: J MHC CINTURA F | AQ18: Ventas | AS18: 10 | AT18: 27 | AU18: 36 | AV18: 28 | AW18: 20 | AX18: 13 | AY18: 0 | AZ18: =SUM(AS18:AY18) -> 134 | BB18: 1420800 | BC18: J MHC CINTURA F | BD18: Ventas | BF18: 9 | BG18: 25 | BH18: 33 | BI18: 26 | BJ18: 19 | BK18: 12 | BL18: 0 | BM18: =SUM(BF18:BL18) -> 124 | BO18: 1420800 | BP18: J MHC CINTURA F | BQ18: Ventas | BS18: 9 | BT18: 25 | BU18: 33 | BV18: 26 | BW18: 19 | BX18: 12 | BY18: 0 | BZ18: =SUM(BS18:BY18) -> 124 | CB18: 1420800 | CC18: J MHC CINTURA F | CD18: Ventas | CF18: 7 | CG18: 22 | CH18: 30 | CI18: 23 | CJ18: 16 | CK18: 10 | CL18: 0 | CM18: =SUM(CF18:CL18) -> 108 | CO18: 1420800 | CP18: J MHC CINTURA F | CQ18: Ventas | CS18: 7 | CT18: 22 | CU18: 30 | CV18: 23 | CW18: 16 | CX18: 10 | CY18: 0 | CZ18: 108 | DB18: 1420800 | DC18: J MHC CINTURA F | DD18: Ventas | DF18: 7 | DG18: 22 | DH18: 30 | DI18: 23 | DJ18: 16 | DK18: 10 | DL18: 0 | DM18: 108 | DO18: 1420800 | DP18: J MHC CINTURA F | DQ18: Ventas | DS18: 0 | DT18: 9 | DU18: 13 | DV18: 12 | DW18: 10 | DX18: 6 | DY18: 0 | DZ18: 50 | EB18: 1420800 | EC18: J MHC CINTURA F | ED18: Ventas | EF18: 0 | EG18: 9 | EH18: 13 | EI18: 12 | EJ18: 10 | EK18: 6 | EL18: 0 | EM18: 50 | EO18: 1420800 | EP18: J MHC CINTURA F | EQ18: Ventas | ES18: 0 | ET18: 9 | EU18: 13 | EV18: 12 | EW18: 10 | EX18: 6 | EY18: 0 | EZ18: 50 | FB18: 1420800 | FC18: J MHC CINTURA F | FD18: Ventas | FF18: 0 | FG18: 9 | FH18: 13 | FI18: 12 | FJ18: 10 | FK18: 6 | FL18: 0 | FM18: 50 | FO18: 1420800 | FP18: J MHC CINTURA F | FQ18: Ventas | FS18: 0 | FT18: 9 | FU18: 13 | FV18: 12 | FW18: 10 | FX18: 6 | FY18: 0 | FZ18: 50 | GB18: 1420800 | GC18: J MHC CINTURA F | GD18: Ventas | GF18: 0 | GG18: 4 | GH18: 8 | GI18: 8 | GJ18: 7 | GK18: 5 | GL18: 0 | GM18: 32 | GO18: 1420800 | GP18: J MHC CINTURA F | GQ18: Ventas | GS18: 0 | GT18: 4 | GU18: 8 | GV18: 8 | GW18: 7 | GX18: 5 | GY18: 0 | GZ18: =SUM(GS18:GY18) -> 32
A19: 1420801 | B19: Ayla | C19: 0 | D19: 4 | E19: 8 | F19: 8 | G19: 7 | H19: 5 | J19: =SUM(C19:H19) -> 32 | K19: ='CORTE 4200'!$O$151 -> 0 | M19: Girar | O19: 1420801 | P19: J MHC CINTURA F | Q19: Ventas | S19: 0 | T19: 4 | U19: 8 | V19: 8 | W19: 7 | X19: 5 | Y19: 0 | Z19: =SUM(S19:Y19) -> 32 | AB19: 1420801 | AC19: J MHC CINTURA F | AD19: Ventas | AF19: 0 | AG19: 4 | AH19: 8 | AI19: 8 | AJ19: 7 | AK19: 5 | AL19: 0 | AM19: =SUM(AF19:AL19) -> 32 | AO19: 1420801 | AP19: J MHC CINTURA F | AQ19: Ventas | AS19: 0 | AT19: 4 | AU19: 8 | AV19: 8 | AW19: 7 | AX19: 5 | AY19: 0 | AZ19: =SUM(AS19:AY19) -> 32 | BB19: 1420801 | BC19: J MHC CINTURA F | BD19: Ventas | BF19: 0 | BG19: 4 | BH19: 8 | BI19: 8 | BJ19: 7 | BK19: 5 | BL19: 0 | BM19: =SUM(BF19:BL19) -> 32 | BO19: 1420801 | BP19: J MHC CINTURA F | BQ19: Ventas | BS19: 0 | BT19: 4 | BU19: 8 | BV19: 8 | BW19: 7 | BX19: 5 | BY19: 0 | BZ19: =SUM(BS19:BY19) -> 32 | CB19: 1420801 | CC19: J MHC CINTURA F | CD19: Ventas | CF19: 0 | CG19: 4 | CH19: 8 | CI19: 8 | CJ19: 7 | CK19: 5 | CL19: 0 | CM19: =SUM(CF19:CL19) -> 32 | CO19: 1420801 | CP19: J MHC CINTURA F | CQ19: Ventas | CS19: 0 | CT19: 4 | CU19: 8 | CV19: 8 | CW19: 7 | CX19: 5 | CY19: 0 | CZ19: 32 | DB19: 1420801 | DC19: J MHC CINTURA F | DD19: Ventas | DF19: 0 | DG19: 4 | DH19: 8 | DI19: 8 | DJ19: 7 | DK19: 5 | DL19: 0 | DM19: 32 | DO19: 1420801 | DP19: J MHC CINTURA F | DQ19: Ventas | DS19: 0 | DT19: 4 | DU19: 8 | DV19: 8 | DW19: 7 | DX19: 5 | DY19: 0 | DZ19: 32 | EB19: 1420801 | EC19: J MHC CINTURA F | ED19: Ventas | EF19: 0 | EG19: 4 | EH19: 8 | EI19: 8 | EJ19: 7 | EK19: 5 | EL19: 0 | EM19: 32 | EO19: 1420801 | EP19: J MHC CINTURA F | EQ19: Ventas | ES19: 0 | ET19: 4 | EU19: 8 | EV19: 8 | EW19: 7 | EX19: 5 | EY19: 0 | EZ19: 32 | FB19: 1420801 | FC19: J MHC CINTURA F | FD19: Ventas | FF19: 0 | FG19: 4 | FH19: 8 | FI19: 8 | FJ19: 7 | FK19: 5 | FL19: 0 | FM19: 32 | FO19: 1420801 | FP19: J MHC CINTURA F | FQ19: Ventas | FS19: 0 | FT19: 4 | FU19: 8 | FV19: 8 | FW19: 7 | FX19: 5 | FY19: 0 | FZ19: 32 | GB19: 1420801 | GC19: J MHC CINTURA F | GD19: Ventas | GF19: 0 | GG19: 4 | GH19: 8 | GI19: 8 | GJ19: 7 | GK19: 5 | GL19: 0 | GM19: 32 | GO19: 1420801 | GP19: J MHC CINTURA F | GQ19: Ventas | GS19: 0 | GT19: 4 | GU19: 8 | GV19: 8 | GW19: 7 | GX19: 5 | GY19: 0 | GZ19: =SUM(GS19:GY19) -> 32
A20: 1420802 | B20: Ayla | C20: 0 | D20: 4 | E20: 8 | F20: 8 | G20: 7 | H20: 5 | J20: =SUM(C20:H20) -> 32 | K20: ='CORTE 4200'!$O$160 -> 0 | M20: Girar | O20: 1420802 | P20: J MHC CINTURA F | Q20: Ventas | S20: 0 | T20: 4 | U20: 8 | V20: 8 | W20: 7 | X20: 5 | Y20: 0 | Z20: =SUM(S20:Y20) -> 32 | AB20: 1420802 | AC20: J MHC CINTURA F | AD20: Ventas | AF20: 0 | AG20: 4 | AH20: 8 | AI20: 8 | AJ20: 7 | AK20: 5 | AL20: 0 | AM20: =SUM(AF20:AL20) -> 32 | AO20: 1420802 | AP20: J MHC CINTURA F | AQ20: Ventas | AS20: 0 | AT20: 4 | AU20: 8 | AV20: 8 | AW20: 7 | AX20: 5 | AY20: 0 | AZ20: =SUM(AS20:AY20) -> 32 | BB20: 1420802 | BC20: J MHC CINTURA F | BD20: Ventas | BF20: 0 | BG20: 4 | BH20: 8 | BI20: 8 | BJ20: 7 | BK20: 5 | BL20: 0 | BM20: =SUM(BF20:BL20) -> 32 | BO20: 1420802 | BP20: J MHC CINTURA F | BQ20: Ventas | BS20: 0 | BT20: 4 | BU20: 8 | BV20: 8 | BW20: 7 | BX20: 5 | BY20: 0 | BZ20: =SUM(BS20:BY20) -> 32 | CB20: 1420802 | CC20: J MHC CINTURA F | CD20: Ventas | CF20: 0 | CG20: 4 | CH20: 8 | CI20: 8 | CJ20: 7 | CK20: 5 | CL20: 0 | CM20: =SUM(CF20:CL20) -> 32 | CO20: 1420802 | CP20: J MHC CINTURA F | CQ20: Ventas | CS20: 0 | CT20: 4 | CU20: 8 | CV20: 8 | CW20: 7 | CX20: 5 | CY20: 0 | CZ20: 32 | DB20: 1420802 | DC20: J MHC CINTURA F | DD20: Ventas | DF20: 0 | DG20: 4 | DH20: 8 | DI20: 8 | DJ20: 7 | DK20: 5 | DL20: 0 | DM20: 32 | DO20: 1420802 | DP20: J MHC CINTURA F | DQ20: Ventas | DS20: 0 | DT20: 4 | DU20: 8 | DV20: 8 | DW20: 7 | DX20: 5 | DY20: 0 | DZ20: 32 | EB20: 1420802 | EC20: J MHC CINTURA F | ED20: Ventas | EF20: 0 | EG20: 4 | EH20: 8 | EI20: 8 | EJ20: 7 | EK20: 5 | EL20: 0 | EM20: 32 | EO20: 1420802 | EP20: J MHC CINTURA F | EQ20: Ventas | ES20: 0 | ET20: 4 | EU20: 8 | EV20: 8 | EW20: 7 | EX20: 5 | EY20: 0 | EZ20: 32 | FB20: 1420802 | FC20: J MHC CINTURA F | FD20: Ventas | FF20: 0 | FG20: 4 | FH20: 8 | FI20: 8 | FJ20: 7 | FK20: 5 | FL20: 0 | FM20: 32 | FO20: 1420802 | FP20: J MHC CINTURA F | FQ20: Ventas | FS20: 0 | FT20: 4 | FU20: 8 | FV20: 8 | FW20: 7 | FX20: 5 | FY20: 0 | FZ20: 32 | GB20: 1420802 | GC20: J MHC CINTURA F | GD20: Ventas | GF20: 0 | GG20: 4 | GH20: 8 | GI20: 8 | GJ20: 7 | GK20: 5 | GL20: 0 | GM20: 32 | GO20: 1420802 | GP20: J MHC CINTURA F | GQ20: Ventas | GS20: 0 | GT20: 4 | GU20: 8 | GV20: 8 | GW20: 7 | GX20: 5 | GY20: 0 | GZ20: =SUM(GS20:GY20) -> 32
A21: 1420900 | B21: B2868-V3 | C21: 55 | D21: 109 | E21: 112 | F21: 103 | G21: 78 | H21: 55 | J21: =SUM(C21:H21) -> 512 | K21: ='CORTE 4200'!$O$169 -> 10 | O21: 1420900 | P21: J MHC MEDIO PIT | Q21: Ventas | S21: 55 | T21: 109 | U21: 112 | V21: 103 | W21: 78 | X21: 55 | Y21: 0 | Z21: =SUM(S21:Y21) -> 512 | AB21: 1420900 | AC21: J MHC MEDIO PIT | AD21: Ventas | AF21: 54 | AG21: 107 | AH21: 110 | AI21: 101 | AJ21: 77 | AK21: 54 | AL21: 0 | AM21: =SUM(AF21:AL21) -> 503 | AO21: 1420900 | AP21: J MHC MEDIO PIT | AQ21: Ventas | AS21: 54 | AT21: 107 | AU21: 110 | AV21: 101 | AW21: 77 | AX21: 54 | AY21: 0 | AZ21: =SUM(AS21:AY21) -> 503 | BB21: 1420900 | BC21: J MHC MEDIO PIT | BD21: Ventas | BF21: 54 | BG21: 107 | BH21: 110 | BI21: 101 | BJ21: 77 | BK21: 54 | BL21: 0 | BM21: =SUM(BF21:BL21) -> 503 | BO21: 1420900 | BP21: J MHC MEDIO PIT | BQ21: Ventas | BS21: 54 | BT21: 107 | BU21: 110 | BV21: 101 | BW21: 77 | BX21: 54 | BY21: 0 | BZ21: =SUM(BS21:BY21) -> 503 | CB21: 1420900 | CC21: J MHC MEDIO PIT | CD21: Ventas | CF21: 52 | CG21: 104 | CH21: 107 | CI21: 98 | CJ21: 74 | CK21: 52 | CL21: 0 | CM21: =SUM(CF21:CL21) -> 487 | CO21: 1420900 | CP21: J MHC MEDIO PIT | CQ21: Ventas | CS21: 52 | CT21: 103 | CU21: 106 | CV21: 97 | CW21: 73 | CX21: 52 | CY21: 0 | CZ21: 483 | DB21: 1420900 | DC21: J MHC MEDIO PIT | DD21: Ventas | DF21: 47 | DG21: 92 | DH21: 94 | DI21: 86 | DJ21: 63 | DK21: 46 | DL21: 0 | DM21: 428 | DO21: 1420900 | DP21: J MHC MEDIO PIT | DQ21: Ventas | DS21: 46 | DT21: 88 | DU21: 92 | DV21: 85 | DW21: 62 | DX21: 46 | DY21: 0 | DZ21: 419 | EB21: 1420900 | EC21: J MHC MEDIO PIT | ED21: Ventas | EF21: 46 | EG21: 87 | EH21: 91 | EI21: 84 | EJ21: 62 | EK21: 46 | EL21: 0 | EM21: 416 | EO21: 1420900 | EP21: J MHC MEDIO PIT | EQ21: Ventas | ES21: 42 | ET21: 82 | EU21: 86 | EV21: 80 | EW21: 59 | EX21: 44 | EY21: 0 | EZ21: 393 | FB21: 1420900 | FC21: J MHC MEDIO PIT | FD21: Ventas | FF21: 36 | FG21: 69 | FH21: 73 | FI21: 67 | FJ21: 48 | FK21: 38 | FL21: 0 | FM21: 331 | FO21: 1420900 | FP21: J MHC MEDIO PIT | FQ21: Ventas | FS21: 36 | FT21: 69 | FU21: 73 | FV21: 67 | FW21: 48 | FX21: 38 | FY21: 0 | FZ21: 331 | GB21: 1420900 | GC21: J MHC MEDIO PIT | GD21: Ventas | GF21: 22 | GG21: 32 | GH21: 33 | GI21: 30 | GJ21: 23 | GK21: 16 | GL21: 0 | GM21: 156 | GO21: 1420900 | GP21: J MHC MEDIO PIT | GQ21: Ventas | GS21: 20 | GT21: 30 | GU21: 30 | GV21: 27 | GW21: 21 | GX21: 14 | GY21: 0 | GZ21: =SUM(GS21:GY21) -> 142
A22: 1421000 | B22: Ayla | C22: 7 | D22: 26 | E22: 30 | F22: 29 | G22: 21 | H22: 16 | J22: =SUM(C22:H22) -> 129 | K22: ='CORTE 4200'!$O$178 -> -20 | M22: Girar | O22: 1421000 | P22: J MHC MEDIO OXF | Q22: Ventas | S22: 7 | T22: 26 | U22: 30 | V22: 29 | W22: 21 | X22: 16 | Y22: 0 | Z22: =SUM(S22:Y22) -> 129 | AB22: 1421000 | AC22: J MHC MEDIO OXF | AD22: Ventas | AF22: 9 | AG22: 32 | AH22: 34 | AI22: 32 | AJ22: 22 | AK22: 16 | AL22: 0 | AM22: =SUM(AF22:AL22) -> 145 | AO22: 1421000 | AP22: J MHC MEDIO OXF | AQ22: Ventas | AS22: 9 | AT22: 32 | AU22: 34 | AV22: 32 | AW22: 22 | AX22: 16 | AY22: 0 | AZ22: =SUM(AS22:AY22) -> 145 | BB22: 1421000 | BC22: J MHC MEDIO OXF | BD22: Ventas | BF22: 9 | BG22: 32 | BH22: 34 | BI22: 32 | BJ22: 22 | BK22: 16 | BL22: 0 | BM22: =SUM(BF22:BL22) -> 145 | BO22: 1421000 | BP22: J MHC MEDIO OXF | BQ22: Ventas | BS22: 9 | BT22: 32 | BU22: 34 | BV22: 32 | BW22: 22 | BX22: 16 | BY22: 0 | BZ22: =SUM(BS22:BY22) -> 145 | CB22: 1421000 | CC22: J MHC MEDIO OXF | CD22: Ventas | CF22: 9 | CG22: 32 | CH22: 34 | CI22: 32 | CJ22: 22 | CK22: 16 | CL22: 0 | CM22: =SUM(CF22:CL22) -> 145 | CO22: 1421000 | CP22: J MHC MEDIO OXF | CQ22: Ventas | CS22: 9 | CT22: 32 | CU22: 34 | CV22: 32 | CW22: 22 | CX22: 16 | CY22: 0 | CZ22: 145 | DB22: 1421000 | DC22: J MHC MEDIO OXF | DD22: Ventas | DF22: 9 | DG22: 32 | DH22: 34 | DI22: 32 | DJ22: 22 | DK22: 16 | DL22: 0 | DM22: 145 | DO22: 1421000 | DP22: J MHC MEDIO OXF | DQ22: Ventas | DS22: 9 | DT22: 32 | DU22: 34 | DV22: 32 | DW22: 22 | DX22: 16 | DY22: 0 | DZ22: 145 | EB22: 1421000 | EC22: J MHC MEDIO OXF | ED22: Ventas | EF22: 7 | EG22: 26 | EH22: 30 | EI22: 29 | EJ22: 21 | EK22: 16 | EL22: 0 | EM22: 129 | EO22: 1421000 | EP22: J MHC MEDIO OXF | EQ22: Ventas | ES22: 7 | ET22: 26 | EU22: 30 | EV22: 29 | EW22: 21 | EX22: 16 | EY22: 0 | EZ22: 129 | FB22: 1421000 | FC22: J MHC MEDIO OXF | FD22: Ventas | FF22: 7 | FG22: 26 | FH22: 30 | FI22: 29 | FJ22: 21 | FK22: 16 | FL22: 0 | FM22: 129 | FO22: 1421000 | FP22: J MHC MEDIO OXF | FQ22: Ventas | FS22: 5 | FT22: 20 | FU22: 24 | FV22: 23 | FW22: 17 | FX22: 12 | FY22: 0 | FZ22: 101 | GB22: 1421000 | GC22: J MHC MEDIO OXF | GD22: Ventas | GF22: 2 | GG22: 11 | GH22: 15 | GI22: 14 | GJ22: 11 | GK22: 6 | GL22: 0 | GM22: 59 | GO22: 1421000 | GP22: J MHC MEDIO OXF | GQ22: Ventas | GS22: 2 | GT22: 11 | GU22: 15 | GV22: 14 | GW22: 11 | GX22: 6 | GY22: 0 | GZ22: =SUM(GS22:GY22) -> 59
A23: 1421001 | B23: Ayla | C23: 5 | D23: 14 | E23: 15 | F23: 12 | G23: 8 | H23: 4 | J23: =SUM(C23:H23) -> 58 | K23: ='CORTE 4200'!$O$187 -> -23 | M23: Girar | O23: 1421001 | P23: J MHC MEDIO REC | Q23: Ventas | S23: 5 | T23: 14 | U23: 15 | V23: 12 | W23: 8 | X23: 4 | Y23: 0 | Z23: =SUM(S23:Y23) -> 58 | AB23: 1421001 | AC23: J MHC MEDIO REC | AD23: Ventas | AF23: 8 | AG23: 21 | AH23: 22 | AI23: 15 | AJ23: 10 | AK23: 5 | AL23: 0 | AM23: =SUM(AF23:AL23) -> 81 | AO23: 1421001 | AP23: J MHC MEDIO REC | AQ23: Ventas | AS23: 8 | AT23: 21 | AU23: 22 | AV23: 15 | AW23: 10 | AX23: 5 | AY23: 0 | AZ23: =SUM(AS23:AY23) -> 81 | BB23: 1421001 | BC23: J MHC MEDIO REC | BD23: Ventas | BF23: 8 | BG23: 21 | BH23: 22 | BI23: 15 | BJ23: 10 | BK23: 5 | BL23: 0 | BM23: =SUM(BF23:BL23) -> 81 | BO23: 1421001 | BP23: J MHC MEDIO REC | BQ23: Ventas | BS23: 6 | BT23: 18 | BU23: 19 | BV23: 13 | BW23: 9 | BX23: 5 | BY23: 0 | BZ23: =SUM(BS23:BY23) -> 70 | CB23: 1421001 | CC23: J MHC MEDIO REC | CD23: Ventas | CF23: 6 | CG23: 18 | CH23: 19 | CI23: 13 | CJ23: 9 | CK23: 5 | CL23: 0 | CM23: =SUM(CF23:CL23) -> 70 | CO23: 1421001 | CP23: J MHC MEDIO REC | CQ23: Ventas | CS23: 6 | CT23: 18 | CU23: 19 | CV23: 13 | CW23: 9 | CX23: 5 | CY23: 0 | CZ23: 70 | DB23: 1421001 | DC23: J MHC MEDIO REC | DD23: Ventas | DF23: 6 | DG23: 18 | DH23: 19 | DI23: 13 | DJ23: 9 | DK23: 5 | DL23: 0 | DM23: 70 | DO23: 1421001 | DP23: J MHC MEDIO REC | DQ23: Ventas | DS23: 6 | DT23: 18 | DU23: 19 | DV23: 13 | DW23: 9 | DX23: 5 | DY23: 0 | DZ23: 70 | EB23: 1421001 | EC23: J MHC MEDIO REC | ED23: Ventas | EF23: 3 | EG23: 11 | EH23: 12 | EI23: 10 | EJ23: 7 | EK23: 4 | EL23: 0 | EM23: 47 | EO23: 1421001 | EP23: J MHC MEDIO REC | EQ23: Ventas | ES23: 3 | ET23: 11 | EU23: 12 | EV23: 10 | EW23: 7 | EX23: 4 | EY23: 0 | EZ23: 47 | FB23: 1421001 | FC23: J MHC MEDIO REC | FD23: Ventas | FF23: 1 | FG23: 8 | FH23: 9 | FI23: 7 | FJ23: 5 | FK23: 2 | FL23: 0 | FM23: 32 | FO23: 1421001 | FP23: J MHC MEDIO REC | FQ23: Ventas | FS23: 1 | FT23: 8 | FU23: 9 | FV23: 7 | FW23: 5 | FX23: 2 | FY23: 0 | FZ23: 32 | GB23: 1421001 | GC23: J MHC MEDIO REC | GD23: Ventas | GF23: 1 | GG23: 8 | GH23: 9 | GI23: 7 | GJ23: 5 | GK23: 2 | GL23: 0 | GM23: 32 | GO23: 1421001 | GP23: J MHC MEDIO REC | GQ23: Ventas | GS23: 0 | GT23: 5 | GU23: 5 | GV23: 4 | GW23: 3 | GX23: 1 | GY23: 0 | GZ23: =SUM(GS23:GY23) -> 18
