Workbook

Sheet cole 37
B2: INVENTARIO COLECCIÓN 37
B3: CODIGO | C3: TIRO | D3: BOTA | E3: COLOR | F3: 36 | G3: 38 | H3: 40 | I3: 42 | J3: 44 | K3: 46 | L3: TOTAL
B4: 372801 | C4: CINTURA | D4: PITILLO | F4: 18 | G4: 28 | H4: 9 | I4: 6 | L4: =SUM(F4:K4) -> 61
B5: 376501 | C5: CINTURA | D5: TOBILLERO | F5: 27 | G5: 12 | H5: 6 | L5: =SUM(F5:K5) -> 45
B6: 373200 | C6: CINTURA | D6: FLARE | F6: 28 | H6: 3 | K6: 3 | L6: =SUM(F6:K6) -> 34
B7: 373300 | C7: CINTURA | D7: TOBILLERO | J7: 22 | K7: 8 | L7: =SUM(F7:K7) -> 30
B8: 373600 | C8: MEDIO | D8: PITILLO | F8: 14 | G8: 13 | J8: 1 | L8: =SUM(F8:K8) -> 28
B9: 375201 | C9: CINTURA | D9: PITILLO | J9: 15 | L9: =SUM(F9:K9) -> 15
B10: 053749 | C10: FALDA | G10: 2 | H10: 4 | I10: 4 | J10: 4 | K10: 1 | L10: =SUM(F10:K10) -> 15
B11: 373400 | C11: MEDIO | D11: OXFORD | F11: 14 | L11: =SUM(F11:K11) -> 14
B12: 376800 | C12: CINTURA | D12: RECTO | F12: 7 | G12: 6 | L12: =SUM(F12:K12) -> 13
B13: 375301 | C13: CINTURA | D13: PITILLO | H13: 5 | I13: 6 | J13: 1 | L13: =SUM(F13:K13) -> 12
B14: 374506 | C14: CINTURA | D14: PITILLO | F14: 0 | G14: 0 | H14: 0 | I14: 5 | J14: 4 | K14: 3 | L14: =SUM(F14:K14) -> 12
B15: 372100 | C15: CINTURA | D15: PITILLO | F15: 11 | G15: 1 | L15: =SUM(F15:K15) -> 12
B16: 376400 | C16: CINTURA | D16: FLARE | K16: 11 | L16: =SUM(F16:K16) -> 11
B17: 372600 | C17: CINTURA | D17: RECTO | G17: 3 | H17: 3 | I17: 1 | J17: 2 | K17: 1 | L17: =SUM(F17:K17) -> 10
B18: 378700 | C18: CINTURA | D18: PALAZZO | F18: 9 | L18: =SUM(F18:K18) -> 9
B19: 374000 | C19: CINTURA | D19: FLARE | F19: 2 | G19: 1 | H19: 5 | L19: =SUM(F19:K19) -> 8
B20: 377700 | C20: CINTURA | D20: OXFORD | F20: 1 | H20: 2 | I20: 2 | J20: 1 | K20: 1 | L20: =SUM(F20:K20) -> 7
B21: 376900 | C21: CINTURA | D21: PALAZZO | I21: 7 | L21: =SUM(F21:K21) -> 7
B22: 371300 | C22: CINTURA | D22: PITILLO | K22: 6 | L22: =SUM(F22:K22) -> 6
B23: 376300 | C23: MEDIO | D23: TOBILLERO | F23: 5 | L23: =SUM(F23:K23) -> 5
B24: 376600 | C24: MEDIO | D24: PITILLO | F24: 5 | L24: =SUM(F24:K24) -> 5
B25: 371100 | C25: CINTURA | D25: FLARE | F25: 4 | L25: =SUM(F25:K25) -> 4
B26: 372300 | C26: CINTURA | D26: FLARE | K26: 3 | L26: =SUM(F26:K26) -> 3
B27: 315700 | C27: MEDIO | D27: PALAZZO | F27: 1 | I27: 1 | L27: =SUM(F27:K27) -> 2
B28: 375300 | C28: CINTURA | D28: PITILLO | G28: 1 | I28: 1 | L28: =SUM(F28:K28) -> 2
B29: 5370800 | C29: FALDA | I29: 2 | L29: =SUM(F29:K29) -> 2
B30: 5378300 | C30: FALDA | H30: 2 | L30: =SUM(F30:K30) -> 2
B31: 376000 | C31: CINTURA | D31: FLARE | J31: 1 | L31: =SUM(F31:K31) -> 1
L34: =SUM(L4:L33) -> 375

Sheet cole 38
B3: INVENTARIO COLECCIÓN 38 | N3: 46029 | O3: 0.66666667
B4: CODIGO | C4: TIRO | D4: BOTA | E4: COLOR | F4: 36 | G4: 38 | H4: 40 | I4: 42 | J4: 44 | K4: 46 | L4: TOTAL
B5: 389201 | C5: CINTURA | D5: RECTO | F5: 4 | G5: 29 | H5: 27 | I5: 30 | J5: 23 | K5: 16 | L5: =SUM(F5:K5) -> 129
B6: 380200 | C6: CINTURA | D6: OXFORD | F6: 14 | G6: 37 | H6: 35 | I6: 31 | J6: 18 | K6: 2 | L6: =SUM(F6:K6) -> 137
B7: 382100 | C7: MEDIO | D7: OXFORD | G7: 0 | H7: 0 | I7: 0 | J7: 0 | K7: 0 | L7: =SUM(F7:K7) -> 0
B8: 388000 | C8: CINTURA | D8: TOBILLERO | F8: 39 | G8: 26 | H8: 0 | I8: 0 | J8: 0 | K8: 0 | L8: =SUM(F8:K8) -> 65
B9: 389300 | C9: CINTURA | D9: PALAZZO | F9: 0 | G9: 12 | H9: 0 | I9: 12 | J9: 8 | K9: 18 | L9: =SUM(F9:K9) -> 50
B10: 385371 | C10: CINTURA | D10: OXFORD | F10: 7 | G10: 11 | H10: 11 | I10: 9 | J10: 3 | K10: 2 | L10: =SUM(F10:K10) -> 43
B11: 386501 | C11: CINTURA | D11: FLARE | F11: 0 | G11: 13 | H11: 7 | I11: 7 | J11: 0 | K11: 0 | L11: =SUM(F11:K11) -> 27
B12: 385304 | C12: CINTURA | D12: OXFORD | F12: 0 | G12: 5 | H12: 3 | I12: 6 | J12: 9 | K12: 0 | L12: =SUM(F12:K12) -> 23
B13: 388300 | C13: CINTURA | D13: RECTO | F13: 17 | G13: 12 | H13: 0 | I13: 0 | J13: 0 | K13: 0 | L13: =SUM(F13:K13) -> 29
B14: 387900 | C14: MEDIO | D14: PITILLO | F14: 28 | G14: 3 | H14: 0 | I14: 0 | J14: 0 | K14: 0 | L14: =SUM(F14:K14) -> 31
B15: 385800 | C15: CINTURA | D15: RECTO | F15: 8 | G15: 0 | H15: 0 | I15: 0 | J15: 9 | K15: 0 | L15: =SUM(F15:K15) -> 17
B16: 381801 | C16: CINTURA | D16: RECTO | F16: 10 | G16: 2 | H16: 0 | I16: 0 | J16: 1 | K16: 0 | L16: =SUM(F16:K16) -> 13
B17: 389401 | C17: CINTURA | D17: PITILLO | F17: 10 | G17: 0 | H17: 0 | I17: 3 | J17: 0 | K17: 0 | L17: =SUM(F17:K17) -> 13
B18: 382101 | C18: MEDIO | D18: PALAZZO | F18: 1 | G18: 2 | H18: 0 | I18: 1 | J18: 1 | K18: 0 | L18: =SUM(F18:K18) -> 5
B19: 389700 | C19: CINTURA | D19: FLARE | F19: 6 | G19: 0 | H19: 0 | I19: 0 | J19: 0 | K19: 0 | L19: =SUM(F19:K19) -> 6
L22: =SUM(L5:L21) -> 588

Sheet cole39
B3: INVENTARIO COLECCIÓN 39
B4: CODIGO | C4: TIRO | D4: BOTA | E4: COLOR | F4: 36 | G4: 38 | H4: 40 | I4: 42 | J4: 44 | K4: 46 | L4: TOTAL
B5: 394001 | C5: CARGO | D5: RECTO | F5: 15 | G5: 15 | H5: 19 | I5: 20 | J5: 15 | K5: 11 | L5: =SUM(F5:K5) -> 95
B6: 397100 | C6: CINTURA | D6: PALAZZO | F6: 17 | G6: 22 | H6: 15 | J6: 1 | L6: =SUM(F6:K6) -> 55
B7: 395400 | C7: CINTURA | D7: FLARE | G7: 5 | H7: 6 | I7: 20 | K7: 7 | L7: =SUM(F7:K7) -> 38
B8: 390600 | C8: CINTURA | D8: OXFORD | G8: 5 | H8: 13 | I8: 9 | K8: 1 | L8: =SUM(F8:K8) -> 28
B9: 393700 | C9: CINTURA | D9: OXFORD | H9: 6 | I9: 13 | K9: 4 | L9: =SUM(F9:K9) -> 23
B10: 396000 | C10: CINTURA | D10: PALAZZO | F10: 8 | J10: 9 | L10: =SUM(F10:K10) -> 17
B11: 394400 | C11: CINTURA | D11: PALAZZO | I11: 7 | J11: 6 | K11: 1 | L11: =SUM(F11:K11) -> 14
B12: 390500 | C12: CINTURA | D12: FLARE | J12: 4 | K12: 5 | L12: =SUM(F12:K12) -> 9
B13: 394100 | C13: CINTURA | D13: PITILLO | F13: 5 | L13: =SUM(F13:K13) -> 5
B14: 392101 | C14: CINTURA | D14: PITILLO | G14: 4 | L14: =SUM(F14:K14) -> 4
B15: 391501 | C15: CINTURA | D15: PITILLO | F15: 1 | L15: =SUM(F15:K15) -> 1
L19: =SUM(L5:L18) -> 289

Sheet COLE 40 prima
B3: INVENTARIO COLECCIÓN 40
B4: CODIGO | C4: TIRO | D4: BOTA | E4: COLOR | F4: 36 | G4: 38 | H4: 40 | I4: 42 | J4: 44 | K4: 46 | L4: TOTAL
B5: 4004-00 | C5: CINTURA | D5: OXFORD | F5: 9 | G5: 24 | H5: 28 | I5: 23 | J5: 10 | K5: 10 | L5: =SUM(F5:K5) -> 104
B6: 4021-90 | C6: CINTURA | D6: PITILLO | F6: 25 | G6: 22 | H6: 18 | I6: 20 | J6: 8 | K6: 3 | L6: =SUM(F6:K6) -> 96
B7: 4059 | C7: CINTURA | D7: RECTO | E7: NEGRO | F7: 7 | G7: 30 | H7: 18 | I7: 7 | J7: 0 | K7: 0 | L7: =SUM(F7:K7) -> 62
B8: 4066 | C8: CINTURA | D8: FLARE | F8: 20 | G8: 15 | H8: 12 | I8: 3 | J8: 3 | K8: 1 | L8: =SUM(F8:K8) -> 54
B9: 4062-00 | C9: CINTURA | D9: FLARE | F9: 0 | G9: 21 | H9: 10 | I9: 12 | J9: 6 | K9: 2 | L9: =SUM(F9:K9) -> 51
B10: 4009 | C10: CINTURA | D10: OXFORD | F10: 21 | G10: 14 | H10: 10 | I10: 0 | J10: 0 | K10: 0 | L10: =SUM(F10:K10) -> 45
B11: 4063 | C11: CINTURA | D11: PALAZZO CGO | F11: 5 | G11: 7 | H11: 10 | I11: 13 | J11: 6 | K11: 4 | L11: =SUM(F11:K11) -> 45
B12: 4002 | C12: MEDIO | D12: OXFORD | F12: 10 | G12: 1 | H12: 3 | I12: 7 | J12: 13 | K12: 1 | L12: =SUM(F12:K12) -> 35
B13: 4016 | C13: CINTURA | D13: PITILLO (BLUE) | E13: BIOMEDIOFOCALIZADO | F13: 18 | G13: 2 | H13: 8 | I13: 2 | J13: 2 | K13: 3 | L13: =SUM(F13:K13) -> 35
B14: 4012-01 | C14: CINTURA | D14: FLARE | F14: 9 | G14: 0 | H14: 0 | I14: 0 | J14: 12 | K14: 1 | L14: =SUM(F14:K14) -> 22
B15: 4024 | C15: CINTURA | D15: PALAZZO | F15: 0 | G15: 10 | H15: 6 | I15: 6 | J15: 0 | K15: 0 | L15: =SUM(F15:K15) -> 22
B16: 4060-06 | C16: CINTURA | D16: PITILLO | F16: 7 | G16: 3 | H16: 1 | I16: 3 | J16: 3 | K16: 4 | L16: =SUM(F16:K16) -> 21
B17: 4051 | C17: CINTURA | D17: PITILLO | F17: 2 | G17: 6 | H17: 8 | I17: 0 | J17: 2 | K17: 0 | L17: =SUM(F17:K17) -> 18
B18: 4002-01 | C18: MEDIO | D18: OXFORD | F18: 3 | G18: 7 | H18: 5 | I18: 1 | J18: 0 | K18: 0 | L18: =SUM(F18:K18) -> 16
B19: 4023 | C19: CINTURA | D19: PITILLO | F19: 1 | G19: 10 | H19: 5 | I19: 0 | J19: 0 | K19: 0 | L19: =SUM(F19:K19) -> 16
B20: 4007 | C20: CINTURA | D20: PITILLO | F20: 7 | G20: 0 | H20: 1 | I20: 0 | J20: 2 | K20: 5 | L20: =SUM(F20:K20) -> 15
B21: 4019 | C21: MEDIO | D21: PITILLO | F21: 5 | G21: 1 | H21: 4 | I21: 0 | J21: 0 | K21: 2 | L21: =SUM(F21:K21) -> 12
B22: 4011 | C22: CINTURA | D22: FLARE | F22: 11 | G22: 0 | H22: 0 | I22: 0 | J22: 0 | K22: 0 | L22: =SUM(F22:K22) -> 11
B23: 4059-01 | C23: MEDIO | D23: RECTO | F23: 7 | G23: 0 | H23: 0 | I23: 0 | J23: 1 | K23: 0 | L23: =SUM(F23:K23) -> 8
B24: 4060-00 | C24: MEDIO | D24: FLARE | F24: 1 | G24: 0 | H24: 0 | I24: 0 | J24: 4 | K24: 2 | L24: =SUM(F24:K24) -> 7
B25: 4061-00 | C25: CINTURA | D25: PALAZZO | F25: 0 | G25: 0 | H25: 2 | I25: 0 | J25: 2 | K25: 3 | L25: =SUM(F25:K25) -> 7
... B49: 4076 | C49: CINTURA | D49: RECTO | F49: 0 | G49: 0 | H49: 0 | I49: 0 | J49: 0 | K49: 0 | L49: =SUM(F49:K49) -> 0
L50: =SUM(L5:L49) -> 730

Sheet COLE 41 Alto v
B3: INVENTARIO COLECCIÓN 41
B4: CODIGO | C4: TIRO | D4: BOTA | E4: COLOR | F4: 36 | G4: 38 | H4: 40 | I4: 42 | J4: 44 | K4: 46 | L4: TOTAL | M4: 46029 | N4: 16:00HRS
B5: 4113-00 | C5: MEDIO | D5: FLARE | F5: 0 | G5: 3 | H5: 15 | I5: 7 | J5: 16 | K5: 7 | L5: =SUM(F5:K5) -> 48
B6: 05-4119 | C6: CINTURA | D6: MINI | E6: FALDA | F6: 5 | G6: 11 | H6: 12 | I6: 6 | J6: 6 | K6: 2 | L6: =SUM(F6:K6) -> 42
B7: 4188-00 | C7: MEDIO | D7: OXFORD | F7: 6 | G7: 5 | H7: 6 | I7: 4 | J7: 4 | K7: 0 | L7: =SUM(F7:K7) -> 25
B8: 4148-00 | C8: CINTURA | D8: TOBILLERO | F8: 3 | G8: 4 | H8: 4 | I8: 4 | J8: 3 | K8: 2 | L8: =SUM(F8:K8) -> 20
B9: 4188-90 | C9: CINTURA | D9: PALAZZO | E9: GLITTER | F9: 6 | G9: 5 | H9: 6 | I9: 4 | J9: 4 | K9: 0 | L9: =SUM(F9:K9) -> 25
B10: 4158-00 | C10: CINTURA | D10: RECTO | F10: 2 | G10: 4 | H10: 3 | I10: 0 | J10: 0 | K10: 2 | L10: =SUM(F10:K10) -> 11
B11: 4125-00 | C11: CINTURA | D11: PALAZZO | F11: 3 | G11: 3 | H11: 2 | I11: 0 | J11: 0 | K11: 1 | L11: =SUM(F11:K11) -> 9
B12: 4116-00 | C12: CINTURA | D12: OXFORD | F12: 0 | G12: 0 | H12: 0 | I12: 0 | J12: 0 | K12: 0 | L12: =SUM(F12:K12) -> 0
B13: 4177-08 | C13: CINTURA | D13: FLARE | E13: OCRE | F13: 3 | G13: 1 | H13: 0 | I13: 0 | J13: 0 | K13: 1 | L13: =SUM(F13:K13) -> 5
B14: 4147-60 | C14: CINTURA | D14: PITILLO | E14: COLOR TACHAS | F14: 0 | G14: 1 | H14: 0 | I14: 0 | J14: 0 | K14: 0 | L14: =SUM(F14:K14) -> 1
B15: 4108-00 | C15: CINTURA | D15: PALAZZO | F15: 0 | G15: 0 | H15: 0 | I15: 0 | J15: 0 | K15: 0 | L15: =SUM(F15:K15) -> 0
B16: 4166-00 | C16: CINTURA | D16: PITILLO | F16: 0 | G16: 0 | H16: 0 | I16: 0 | J16: 0 | K16: 0 | L16: =SUM(F16:K16) -> 0
B17: 4109 | C17: CINTURA | D17: PALAZZO | F17: 0 | G17: 0 | H17: 0 | I17: 0 | J17: 0 | K17: 0 | L17: =SUM(F17:K17) -> 0
B18: 416500 | C18: CINTURA | D18: PITILLO | F18: 0 | G18: 0 | H18: 0 | I18: 0 | J18: 0 | K18: 0 | L18: =SUM(F18:K18) -> 0
L21: =SUM(L5:L20) -> 186

Sheet COLE 42 otoño
E2: INVENTARIO COLECCIÓN 42
B3: CODIGO | C3: TIRO | D3: BOTA | E3: COLOR | F3: 36 | G3: 38 | H3: 40 | I3: 42 | J3: 44 | K3: 46 | L3: TOTAL
B4: 422200 | C4: MEDIO | D4: TOBILLERO | E4: bLUE | F4: 0 | G4: 18 | H4: 17 | I4: 14 | J4: 10 | K4: 11 | L4: =SUM(F4:K4) -> 70
B5: 424900 | C5: CINTURA | D5: PALAZZO | E5: MARENGO | F5: 15 | G5: 29 | H5: 34 | I5: 23 | J5: 19 | K5: 5 | L5: =SUM(F5:K5) -> 125
B6: 423600 | C6: CINTURA | D6: PALAZZO | E6: BLUE | F6: 14 | G6: 28 | H6: 19 | I6: 16 | J6: 11 | K6: 16 | L6: =SUM(F6:K6) -> 104
B7: 423500 | C7: CINTURA | D7: PITILLO | E7: BLUE | F7: 9 | G7: 16 | H7: 16 | I7: 20 | J7: 17 | K7: 10 | L7: =SUM(F7:K7) -> 88
B8: 420301 | C8: MEDIO | D8: TOBILLERO | E8: GRAVILLADO GRIS | F8: 4 | G8: 11 | H8: 16 | I8: 21 | J8: 18 | K8: 10 | L8: =SUM(F8:K8) -> 80
B9: 421000 | C9: MEDIO | D9: OXFORD | E9: BLUE | F9: 5 | G9: 15 | H9: 15 | I9: 15 | J9: 10 | K9: 10 | L9: =SUM(F9:K9) -> 70
B10: 422800 | C10: MEDIO | D10: FLARE | E10: NEGRO | F10: 0 | G10: 0 | H10: 28 | I10: 0 | J10: 27 | K10: 0 | L10: =SUM(F10:K10) -> 55
B11: 420800 | C11: CINTURA | D11: FLARE | E11: BLUE | F11: 6 | G11: 11 | H11: 14 | I11: 13 | J11: 6 | K11: 6 | L11: =SUM(F11:K11) -> 56
B12: 422000 | C12: CINTURA | D12: PITILLO | E12: BLUE | F12: 32 | G12: 6 | H12: 8 | I12: 4 | J12: 3 | K12: 0 | L12: =SUM(F12:K12) -> 53
B13: 421400 | C13: CINTURA | D13: OXFORD | E13: NEGRO | F13: 4 | G13: 1 | H13: 5 | I13: 5 | J13: 10 | K13: 24 | L13: =SUM(F13:K13) -> 49
B14: 424400 | C14: CINTURA | D14: PITILLO | E14: BIOMEDIO FOCALIZ | F14: 16 | G14: 10 | H14: 6 | I14: 15 | J14: 0 | K14: 0 | L14: =SUM(F14:K14) -> 47
B15: 424600 | C15: CINTURA | D15: TOBILLERO | E15: BLUE | F15: 3 | G15: 0 | H15: 17 | I15: 12 | J15: 14 | K15: 0 | L15: =SUM(F15:K15) -> 46
... B43: 424300 | C43: CINTURA | D43: PITILLO | E43: BLUE | F43: 0 | G43: 2 | H43: 0 | I43: 0 | J43: 0 | K43: 5 | L43: =SUM(F43:K43) -> 7
B44: 421402 | C44: CINTURA | D44: OXFORD | F44: 0 | G44: 3 | H44: 1 | I44: 4 | J44: 3 | K44: 2 | L44: =SUM(F44:K44) -> 13
B45: 423501 | C45: CINTURA | D45: PITILLO | F45: 2 | G45: 3 | H45: 0 | I45: 2 | J45: 0 | K45: 5 | L45: =SUM(F45:K45) -> 12
B46: 424200 | C46: CINTURA | D46: PALAZZO | F46: 2 | G46: 3 | H46: 1 | I46: 2 | J46: 2 | K46: 1 | L46: =SUM(F46:K46) -> 11
B47: 420501 | C47: CINTURA | D47: OXFORD | F47: 6 | G47: 0 | H47: 0 | I47: 0 | J47: 5 | K47: 1 | L47: =SUM(F47:K47) -> 12
B48: 421401 | C48: CINTURA | D48: OXFORD | F48: 0 | G48: 3 | H48: 6 | I48: 2 | J48: 0 | K48: 1 | L48: =SUM(F48:K48) -> 12
B49: 423900 | C49: CINTURA | D49: FLARE | F49: 0 | G49: 0 | H49: 0 | I49: 0 | J49: 1 | K49: 2 | L49: =SUM(F49:K49) -> 3
B50: 422601 | C50: MEDIO | D50: PITILLO | F50: 0 | G50: 0 | H50: 0 | I50: 0 | J50: 7 | K50: 0 | L50: =SUM(F50:K50) -> 7
B51: 424700 | C51: CINTURA | D51: RECTO | F51: 0 | G51: 0 | H51: 0 | I51: 0 | J51: 0 | K51: 0 | L51: =SUM(F51:K51) -> 0
B52: 421300 | C52: CINTURA | D52: OXFORD | F52: 0 | G52: 0 | H52: 0 | I52: 0 | J52: 0 | K52: 0 | L52: =SUM(F52:K52) -> 0
B53: 424500 | C53: CINTURA | D53: PITILLO | F53: 0 | G53: 0 | H53: 0 | I53: 0 | J53: 0 | K53: 0 | L53: =SUM(F53:K53) -> 0
B54: 424960 | C54: CINTURA | D54: PALAZZO | F54: 1 | G54: 2 | H54: 2 | I54: 2 | J54: 1 | K54: 1 | L54: =SUM(F54:K54) -> 9
B55: 423348 | C55: CINTURA | D55: TOBILLERO | E55: BURDEO | F55: 0 | G55: 2 | H55: 2 | I55: 1 | J55: 3 | K55: 0 | L55: =SUM(F55:K55) -> 8
B56: 421900 | C56: CINTURA | D56: PITILLO | F56: 0 | G56: 0 | H56: 0 | I56: 0 | J56: 0 | K56: 0 | L56: =SUM(F56:K56) -> 0
B57: 420900 | C57: MEDIO | D57: PITILLO | F57: 0 | G57: 0 | H57: 0 | I57: 0 | J57: 0 | K57: 7 | L57: =SUM(F57:K57) -> 7
B58: 421001 | C58: MEDIO | D58: RECTO | F58: 0 | G58: 0 | H58: 2 | I58: 1 | J58: 1 | K58: 2 | L58: =SUM(H58:K58) -> 6
B59: 423309 | C59: CINTURA | D59: TOBILLERO | E59: VERDE MENTA | F59: 0 | G59: 1 | H59: 2 | I59: 2 | J59: 0 | K59: 0 | L59: =SUM(F59:K59) -> 5
B60: 423304 | C60: CINTURA | D60: TOBILLERO | E60: CAFE | F60: 2 | G60: 1 | H60: 1 | I60: 0 | J60: 0 | K60: 0 | L60: =SUM(F60:K60) -> 4
B61: 420402 | C61: MEDIO | D61: FLARE | F61: 0 | G61: 0 | H61: 0 | I61: 0 | J61: 4 | K61: 0 | L61: =SUM(F61:K61) -> 4
B62: 423448 | C62: CINTURA | D62: FLARE | E62: BURDEO | F62: 0 | G62: 0 | H62: 0 | I62: 0 | J62: 4 | K62: 0 | L62: =SUM(F62:K62) -> 4
B63: 423404 | C63: CINTURA | D63: FLARE | E63: CAFE | F63: 0 | G63: 1 | H63: 1 | I63: 1 | J63: 1 | K63: 0 | L63: =SUM(F63:K63) -> 4
B64: 423408 | C64: CINTURA | D64: FLARE | E64: OCRE | F64: 0 | G64: 0 | H64: 0 | I64: 1 | J64: 1 | K64: 0 | L64: =SUM(F64:K64) -> 2
B65: 423308 | C65: CINTURA | D65: TOBILLERO | G65: 2 | L65: =SUM(F65:K65) -> 2
B66: 422400 | C66: MEDIO | D66: OXFORD | F66: 0 | G66: 0 | H66: 0 | I66: 0 | J66: 2 | K66: 0 | L66: =SUM(F66:K66) -> 2
B67: 421101 | C67: CINTURA | D67: FLARE | F67: 0 | G67: 1 | H67: 1 | I67: 0 | L67: =SUM(F67:K67) -> 2
B68: 421460 | C68: CINTURA | D68: OXFORD | E68: TACHAS | F68: 0 | G68: 0 | H68: 0 | I68: 0 | J68: 1 | K68: 0 | L68: =SUM(F68:K68) -> 1
...

Sheet COLE 43
C2: INVENTARIO COLECCIÓN 43
C3: CODIGO | D3: TIRO | E3: BOTA | F3: COLOR | G3: TELA | H3: 36 | I3: 38 | J3: 40 | K3: 42 | L3: 44 | M3: 46 | N3: TOTAL
C4: 435500 | D4: CINTURA | E4: FLARE | G4: B2868V-3 | H4: 12 | I4: 27 | J4: 36 | K4: 27 | L4: 22 | M4: 10 | N4: =SUM(H4:M4) -> 134
C5: 438000 | D5: CINTURA | E5: WIDE LEG CROP | G5: PUGLIA | H5: 18 | I5: 22 | J5: 26 | K5: 26 | L5: 16 | M5: 14 | N5: =SUM(H5:M5) -> 122
C6: 438002 | D6: CINTURA | E6: WIDE LEG CROP | F6: BIO OSCURO | G6: PUGLIA | H6: 17 | I6: 25 | J6: 26 | K6: 23 | L6: 16 | M6: 7 | N6: =SUM(H6:M6) -> 114
A7: TRASPASAR | B7: 44 | C7: 433900 | D7: CINTURA | E7: FLARE | G7: NEW GLUE | H7: 8 | I7: 20 | J7: 20 | K7: 18 | L7: 15 | M7: 20 | N7: =SUM(H7:M7) -> 101
C8: 436604 | D8: CINTURA | E8: RECTO | F8: CAFE | G8: YASMIN | H8: 11 | I8: 16 | J8: 11 | K8: 12 | L8: 6 | M8: 10 | N8: =SUM(H8:M8) -> 66
C9: 436104 | D9: CINTURA | E9: FLARE | F9: CAFE | G9: YASMIN | H9: 10 | I9: 11 | J9: 11 | K9: 10 | L9: 12 | M9: 8 | N9: =SUM(H9:M9) -> 62
C10: 437801 | D10: CINTURA | E10: TOBILLERO | H10: 9 | I10: 11 | J10: 13 | K10: 11 | L10: 8 | M10: 7 | N10: =SUM(H10:M10) -> 59
C11: 433300 | D11: CINTURA | E11: WIDE LEG | G11: MISSY PLUS | H11: 0 | I11: 11 | J11: 10 | K11: 7 | L11: 10 | M11: 17 | N11: =SUM(H11:M11) -> 55
C12: 436648 | D12: CINTURA | E12: RECTO | F12: BURDEO | H12: 9 | I12: 12 | J12: 8 | K12: 8 | L12: 6 | M12: 9 | N12: =SUM(H12:M12) -> 52
C13: 435601 | D13: CINTURA | E13: FLARE | F13: GRIS FOCALIZADO | H13: 0 | I13: 9 | J13: 18 | K13: 5 | L13: 15 | M13: 4 | N13: =SUM(H13:M13) -> 51
C14: 432301 | D14: CINTURA | E14: RECTO | G14: AYLA | H14: 7 | I14: 9 | J14: 10 | K14: 9 | L14: 9 | M14: 7 | N14: =SUM(H14:M14) -> 51
C15: 431100 | D15: CINTURA | E15: RECTO | G15: NEW GLUE | H15: 2 | I15: 15 | J15: 4 | K15: 11 | L15: 6 | M15: 12 | N15: =SUM(H15:M15) -> 50
C16: 433700 | D16: CINTURA | E16: FLARE | G16: OPAQUE | H16: 0 | I16: 4 | J16: 9 | K16: 15 | L16: 9 | M16: 8 | N16: =SUM(H16:M16) -> 45
C17: 436500 | D17: CINTURA | E17: RECTO | G17: AYLA | H17: 5 | I17: 8 | J17: 12 | K17: 13 | L17: 6 | M17: 1 | N17: =SUM(H17:M17) -> 45
C18: 434000 | D18: CINTURA | E18: PALAZZO | G18: MISSY PLUS | H18: 0 | I18: 9 | J18: 12 | K18: 7 | L18: 3 | M18: 0 | N18: =SUM(H18:M18) -> 31
C19: 432500 | D19: CINTURA | E19: WIDE LEG | G19: B2868V-3 | H19: 0 | I19: 0 | J19: 0 | K19: 0 | L19: 7 | M19: 21 | N19: =SUM(H19:M19) -> 28
C20: 436248 | D20: CINTURA | E20: PITILLO | F20: BURDEO | G20: YASMIN | H20: 0 | I20: 2 | J20: 3 | K20: 11 | L20: 1 | M20: 12 | N20: =SUM(H20:M20) -> 29
C21: 436148 | D21: CINTURA | E21: FLARE | H21: 3 | I21: 3 | J21: 6 | K21: 5 | L21: 5 | M21: 5 | N21: =SUM(H21:M21) -> 27
C22: 4370-04 | D22: CINTURA | E22: WIDE LEG | G22: YASMIN | H22: 2 | I22: 5 | J22: 7 | K22: 6 | L22: 4 | M22: 2 | N22: =SUM(H22:M22) -> 26
C23: 436148 | D23: CINTURA | E23: FLARE | F23: BURDEO | H23: 3 | I23: 2 | J23: 4 | K23: 3 | L23: 2 | M23: 5 | N23: =SUM(H23:M23) -> 19
C24: 431000 | D24: CINTURA | E24: TOBILLERO | G24: PATRICIA DARK | H24: 0 | I24: 1 | J24: 3 | K24: 0 | L24: 0 | M24: 15 | N24: =SUM(H24:M24) -> 19
C25: 435300 | D25: CINTURA | E25: FLARE | G25: NEW GLUE | H25: 1 | I25: 5 | J25: 3 | K25: 5 | L25: 2 | M25: 3 | N25: =SUM(H25:M25) -> 19
C26: 436606 | D26: CINTURA | E26: RECTO | F26: BEIGE | G26: YASMIN | H26: 4 | I26: 6 | J26: 0 | K26: 2 | L26: 1 | M26: 4 | N26: =SUM(H26:M26) -> 17
C27: 434100 | D27: CINTURA | E27: FLARE | G27: NEW GLUE | H27: 0 | I27: 0 | J27: 0 | K27: 2 | L27: 0 | M27: 12 | N27: =SUM(H27:M27) -> 14
C28: 432100 | D28: CINTURA | E28: OXFORD | G28: NEW GLUE | H28: 0 | I28: 2 | J28: 3 | K28: 2 | L28: 4 | M28: 3 | N28: =SUM(H28:M28) -> 14
C29: 431800 | D29: CINTURA | E29: WIDE LEG | G29: MISSY PLUS | H29: 0 | I29: 2 | J29: 3 | K29: 2 | L29: 2 | M29: 2 | N29: =SUM(H29:M29) -> 11
C30: 433901 | D30: CINTURA | E30: FLARE | G30: NEW GLUE | H30: 0 | I30: 1 | J30: 3 | K30: 3 | L30: 3 | M30: 1 | N30: =SUM(H30:M30) -> 11
C31: 436167 | D31: CINTURA | E31: FLARE | F31: CAFE ANIMAL PRINT | H31: 2 | I31: 1 | J31: 1 | K31: 1 | L31: 1 | M31: 3 | N31: =SUM(H31:M31) -> 9
C32: 432200 | D32: CINTURA | E32: FLARE | G32: B2868V-3 | H32: 3 | I32: 3 | J32: 0 | K32: 0 | L32: 0 | M32: 2 | N32: =SUM(H32:M32) -> 8
C33: 431300 | D33: CINTURA | E33: FLARE | F33: PUSHIN PUSH UP | G33: NEW GLUE | H33: 0 | I33: 0 | J33: 5 | K33: 0 | L33: 0 | M33: 2 | N33: =SUM(H33:M33) -> 7
C34: 435600 | D34: CINTURA | E34: FLARE | H34: 1 | I34: 0 | J34: 0 | K34: 0 | L34: 6 | M34: 0 | N34: =SUM(H34:M34) -> 7
C35: 432261 | D35: CINTURA | E35: FLARE | F35: GRIS TACHAS | H35: 3 | I35: 0 | J35: 3 | K35: 0 | L35: 0 | M35: 0 | N35: =SUM(H35:M35) -> 6
C36: 434801 | D36: CINTURA | E36: PITILLO | F36: GRAVILLADO | G36: B2868V-3 | H36: 1 | I36: 5 | J36: 0 | K36: 0 | L36: 0 | M36: 0 | N36: =SUM(H36:M36) -> 6
C37: 436116 | D37: CINTURA | E37: FLARE | F37: VERDE OLIVA | H37: 0 | I37: 1 | J37: 0 | K37: 1 | L37: 2 | M37: 2 | N37: =SUM(H37:M37) -> 6
C38: 434861 | D38: CINTURA | E38: PITILLO | F38: TACHAS | H38: 2 | I38: 0 | J38: 0 | K38: 0 | L38: 1 | M38: 2 | N38: =SUM(H38:M38) -> 5
C39: 431900 | D39: MEDIO | E39: FLARE | G39: NEW GLUE | H39: 1 | I39: 2 | J39: 0 | K39: 0 | L39: 1 | M39: 0 | N39: =SUM(H39:M39) -> 4
C40: 436168 | D40: CINTURA | E40: FLARE | F40: BICOLOR | H40: 0 | I40: 2 | J40: 0 | K40: 0 | L40: 1 | M40: 0 | N40: =SUM(H40:M40) -> 3
C41: 434800 | D41: CINTURA | E41: PITILLO | G41: B2868V-3 | H41: 0 | I41: 1 | J41: 1 | K41: 0 | L41: 0 | M41: 0 | N41: =SUM(H41:M41) -> 2
...

Sheet COLE 44
D3: INVENTARIO COLECCIÓN 44
C4: CODIGO | D4: TIRO | E4: BOTA | F4: COLOR | G4: TELA | H4: 36 | I4: 38 | J4: 40 | K4: 42 | L4: 44 | M4: 46 | N4: TOTAL
C5: 444800 | D5: CINTURA | E5: FLARE | F5: BIO MEDIO | G5: NEW GLUE | H5: 58 | I5: 143 | J5: 163 | K5: 160 | L5: 102 | M5: 83 | N5: =SUM(H5:M5) -> 709
C6: 443000 | D6: CINTURA | E6: FLARE | F6: CELESTE | G6: NEW GLUE | H6: 28 | I6: 40 | J6: 60 | K6: 65 | L6: 64 | M6: 47 | N6: =SUM(H6:M6) -> 304
C7: 445500 | D7: CINTURA | E7: PALAZZO | F7: BIO MEDIO | G7: MISSY PLUS | H7: 31 | I7: 56 | J7: 65 | K7: 62 | L7: 42 | M7: 35 | N7: =SUM(H7:M7) -> 291
C8: 441800 | D8: CINTURA | E8: PALAZZO | F8: BIO MEDIO | G8: MISSY PLUS | H8: 20 | I8: 54 | J8: 63 | K8: 61 | L8: 50 | M8: 20 | N8: =SUM(H8:M8) -> 268
C9: 448400 | D9: MEDIO | E9: FLARE | F9: BIO MEDIO | H9: 5 | I9: 40 | J9: 38 | K9: 39 | L9: 38 | M9: 33 | N9: =SUM(H9:M9) -> 193
C10: 447900 | D10: CINTURA | E10: FLARE | F10: CELESTE | G10: MISSY PLUS | H10: 0 | I10: 29 | J10: 42 | K10: 38 | L10: 33 | M10: 36 | N10: =SUM(H10:M10) -> 178
C11: 448500 | D11: CINTURA | E11: RECTO | G11: PATRICIA DARK | H11: 17 | I11: 34 | J11: 37 | K11: 28 | L11: 23 | M11: 28 | N11: =SUM(H11:M11) -> 167
C12: 447600 | D12: MEDIO | E12: OXFORD | G12: NEW GLUE | H12: 5 | I12: 28 | J12: 32 | K12: 40 | L12: 22 | M12: 35 | N12: =SUM(H12:M12) -> 162
C13: 443101 | D13: CINTURA | E13: WIDE LEG | G13: MISSY PLUS | H13: 0 | I13: 43 | J13: 25 | K13: 41 | L13: 29 | M13: 22 | N13: =SUM(H13:M13) -> 160
C14: 445400 | D14: CINTURA | E14: FLARE | F14: BIO MEDIO | G14: NEW GLUE | H14: 8 | I14: 23 | J14: 34 | K14: 29 | L14: 27 | M14: 16 | N14: =SUM(H14:M14) -> 137
C15: 447400 | D15: CINTURA | E15: PITILLO | G15: NEW G MIX BLACK | H15: 7 | I15: 18 | J15: 25 | K15: 24 | L15: 17 | M15: 9 | N15: =SUM(H15:M15) -> 100
C16: 443100 | D16: CINTURA | E16: WIDE LEG | F16: BIO MEDIO | G16: MISSY PLUS | H16: 1 | I16: 20 | J16: 29 | K16: 25 | L16: 4 | M16: 20 | N16: =SUM(H16:M16) -> 99
C17: 447200 | D17: CINTURA | E17: FLARE | G17: NEW GLUE BLUE | H17: 13 | I17: 0 | J17: 1 | K17: 7 | L17: 9 | M17: 7 | N17: =SUM(H17:M17) -> 37
C18: 445300 | D18: CINTURA | E18: RECTO | G18: NEW GLUE BLUE | H18: 0 | I18: 0 | J18: 2 | K18: 4 | L18: 3 | M18: 13 | N18: =SUM(H18:M18) -> 22
C19: 447201 | D19: CINTURA | E19: FLARE | G19: NEW GLUE BLUE | H19: 0 | I19: 0 | J19: 0 | K19: 1 | L19: 5 | M19: 12 | N19: =SUM(H19:M19) -> 18
C20: 447300 | D20: CINTURA | E20: TOBILLOERO | G20: PATRICIA DARK | H20: 7 | I20: 0 | J20: 0 | K20: 2 | L20: 4 | M20: 0 | N20: =SUM(H20:M20) -> 13
N21: =SUM(H21:M21) -> 0
N22: =SUM(H22:M22) -> 0
N23: =SUM(H23:M23) -> 0
N24: =SUM(H24:M24) -> 0
N25: =SUM(H25:M25) -> 0
N26: =SUM(H26:M26) -> 0
N27: =SUM(H27:M27) -> 0
N28: =SUM(H28:M28) -> 0
N29: =SUM(H29:M29) -> 0
N30: =SUM(H30:M30) -> 0
N31: =SUM(H31:M31) -> 0
N32: =SUM(H32:M32) -> 0
... N38: =SUM(H38:M38) -> 0
M40: TOTAL | N40: =SUM(N5:N39) -> 2858

Sheet Hoja1

Sheet Resumen
A1: re
B3: Resumen
B5: Cole 43 | C5: ='COLE 43'!N43 -> 1336
B6: Cole 42 | C6: ='COLE 42 otoño'!L84 -> 1682
B7: Cole 41 | C7: ='COLE 41 Alto v'!L21 -> 186
B8: Cole 40 | C8: ='COLE 40 prima'!L50 -> 730
B9: CoLe 39 | C9: =cole39!L19 -> 289
B10: Cole 38 | C10: ='cole 38'!L22 -> 588
B11: Cole 37 | C11: ='cole 37'!L34 -> 375
C16: =SUM(C5:C15) -> 5186
